
Traceback (most recent call last):
  File "/Users/macuser/Desktop/django/online_class/project/repositories/repository.py", line 38, in get_object
    return self.model.objects.get(**kwargs)
           ^^^^^^^^^^^^^^^^^^^^^^^^^^^^^^^^
  File "/Users/macuser/Desktop/django/online_class/venv/lib/python3.11/site-packages/django/db/models/manager.py", line 87, in manager_method
    return getattr(self.get_queryset(), name)(*args, **kwargs)
           ^^^^^^^^^^^^^^^^^^^^^^^^^^^^^^^^^^^^^^^^^^^^^^^^^^^
  File "/Users/macuser/Desktop/django/online_class/venv/lib/python3.11/site-packages/django/db/models/query.py", line 649, in get
    raise self.model.DoesNotExist(
classes.models.ClassMessage.DoesNotExist: ClassMessage matching query does not exist.

During handling of the above exception, another exception occurred:

Traceback (most recent call last):
  File "/Users/macuser/Desktop/django/online_class/project/classes/views.py", line 75, in get
    response_data = class_service.get_single_message(class_id, message_id)
                    ^^^^^^^^^^^^^^^^^^^^^^^^^^^^^^^^^^^^^^^^^^^^^^^^^^^^^^
  File "/Users/macuser/Desktop/django/online_class/project/classes/services/class_service.py", line 76, in get_single_message
    message = self.messagesRepository.get_object(id=message_id, class_id=class_id)
              ^^^^^^^^^^^^^^^^^^^^^^^^^^^^^^^^^^^^^^^^^^^^^^^^^^^^^^^^^^^^^^^^^^^^
  File "/Users/macuser/Desktop/django/online_class/project/repositories/repository.py", line 40, in get_object
    raise Http404
django.http.response.Http404
Message not found or does not belong to the specified class.
Traceback (most recent call last):
  File "/Users/macuser/Desktop/django/online_class/project/repositories/repository.py", line 38, in get_object
    return self.model.objects.get(**kwargs)
           ^^^^^^^^^^^^^^^^^^^^^^^^^^^^^^^^
  File "/Users/macuser/Desktop/django/online_class/venv/lib/python3.11/site-packages/django/db/models/manager.py", line 87, in manager_method
    return getattr(self.get_queryset(), name)(*args, **kwargs)
           ^^^^^^^^^^^^^^^^^^^^^^^^^^^^^^^^^^^^^^^^^^^^^^^^^^^
  File "/Users/macuser/Desktop/django/online_class/venv/lib/python3.11/site-packages/django/db/models/query.py", line 649, in get
    raise self.model.DoesNotExist(
classes.models.ClassMessage.DoesNotExist: ClassMessage matching query does not exist.

During handling of the above exception, another exception occurred:

Traceback (most recent call last):
  File "/Users/macuser/Desktop/django/online_class/project/classes/services/class_service.py", line 76, in get_single_message
    message = self.messagesRepository.get_object(id=message_id, class_id=class_id)
              ^^^^^^^^^^^^^^^^^^^^^^^^^^^^^^^^^^^^^^^^^^^^^^^^^^^^^^^^^^^^^^^^^^^^
  File "/Users/macuser/Desktop/django/online_class/project/repositories/repository.py", line 40, in get_object
    raise Http404
django.http.response.Http404

During handling of the above exception, another exception occurred:

Traceback (most recent call last):
  File "/Users/macuser/Desktop/django/online_class/project/classes/views.py", line 75, in get
    response_data = class_service.get_single_message(class_id, message_id)
                    ^^^^^^^^^^^^^^^^^^^^^^^^^^^^^^^^^^^^^^^^^^^^^^^^^^^^^^
  File "/Users/macuser/Desktop/django/online_class/project/classes/services/class_service.py", line 78, in get_single_message
    raise Http404("Message not found or does not belong to the specified class.")
django.http.response.Http404: Message not found or does not belong to the specified class.
Class with id 9ca5ca65-bd20-454c-b583-ad2bbd94ef27 does not exist.
Traceback (most recent call last):
  File "/Users/macuser/Desktop/django/online_class/project/repositories/repository.py", line 38, in get_object
    return self.model.objects.get(**kwargs)
           ^^^^^^^^^^^^^^^^^^^^^^^^^^^^^^^^
  File "/Users/macuser/Desktop/django/online_class/venv/lib/python3.11/site-packages/django/db/models/manager.py", line 87, in manager_method
    return getattr(self.get_queryset(), name)(*args, **kwargs)
           ^^^^^^^^^^^^^^^^^^^^^^^^^^^^^^^^^^^^^^^^^^^^^^^^^^^
  File "/Users/macuser/Desktop/django/online_class/venv/lib/python3.11/site-packages/django/db/models/query.py", line 649, in get
    raise self.model.DoesNotExist(
classes.models.OnlineClass.DoesNotExist: OnlineClass matching query does not exist.

During handling of the above exception, another exception occurred:

Traceback (most recent call last):
  File "/Users/macuser/Desktop/django/online_class/project/classes/services/class_service.py", line 71, in get_single_message
    self.repository.get_object(id=class_id)
  File "/Users/macuser/Desktop/django/online_class/project/repositories/repository.py", line 40, in get_object
    raise Http404
django.http.response.Http404

During handling of the above exception, another exception occurred:

Traceback (most recent call last):
  File "/Users/macuser/Desktop/django/online_class/project/classes/views.py", line 75, in get
    response_data = class_service.get_single_message(class_id, message_id)
                    ^^^^^^^^^^^^^^^^^^^^^^^^^^^^^^^^^^^^^^^^^^^^^^^^^^^^^^
  File "/Users/macuser/Desktop/django/online_class/project/classes/services/class_service.py", line 73, in get_single_message
    raise Http404(f"Class with id {class_id} does not exist.")
django.http.response.Http404: Class with id 9ca5ca65-bd20-454c-b583-ad2bbd94ef27 does not exist.
Internal Server Error: /api/classes/class/8ca5ca65-bd20-454c-b583-ad2bbd94ef27/message/197fb606-fb6c-476f-bc99-0575eabd15c3/
Traceback (most recent call last):
  File "/Users/macuser/Desktop/django/online_class/venv/lib/python3.11/site-packages/asgiref/sync.py", line 534, in thread_handler
    raise exc_info[1]
  File "/Users/macuser/Desktop/django/online_class/venv/lib/python3.11/site-packages/django/core/handlers/exception.py", line 42, in inner
    response = await get_response(request)
               ^^^^^^^^^^^^^^^^^^^^^^^^^^^
  File "/Users/macuser/Desktop/django/online_class/venv/lib/python3.11/site-packages/asgiref/sync.py", line 534, in thread_handler
    raise exc_info[1]
  File "/Users/macuser/Desktop/django/online_class/venv/lib/python3.11/site-packages/django/core/handlers/base.py", line 284, in _get_response_async
    response = await sync_to_async(
               ^^^^^^^^^^^^^^^^^^^^
  File "/Users/macuser/Desktop/django/online_class/venv/lib/python3.11/site-packages/asgiref/sync.py", line 479, in __call__
    ret: _R = await loop.run_in_executor(
              ^^^^^^^^^^^^^^^^^^^^^^^^^^^
  File "/usr/local/Cellar/python@3.11/3.11.6_1/Frameworks/Python.framework/Versions/3.11/lib/python3.11/concurrent/futures/thread.py", line 58, in run
    result = self.fn(*self.args, **self.kwargs)
             ^^^^^^^^^^^^^^^^^^^^^^^^^^^^^^^^^^
  File "/Users/macuser/Desktop/django/online_class/venv/lib/python3.11/site-packages/asgiref/sync.py", line 538, in thread_handler
    return func(*args, **kwargs)
           ^^^^^^^^^^^^^^^^^^^^^
  File "/Users/macuser/Desktop/django/online_class/venv/lib/python3.11/site-packages/django/template/response.py", line 114, in render
    self.content = self.rendered_content
                   ^^^^^^^^^^^^^^^^^^^^^
  File "/Users/macuser/Desktop/django/online_class/venv/lib/python3.11/site-packages/rest_framework/response.py", line 70, in rendered_content
    ret = renderer.render(self.data, accepted_media_type, context)
          ^^^^^^^^^^^^^^^^^^^^^^^^^^^^^^^^^^^^^^^^^^^^^^^^^^^^^^^^
  File "/Users/macuser/Desktop/django/online_class/venv/lib/python3.11/site-packages/rest_framework/renderers.py", line 99, in render
    ret = json.dumps(
          ^^^^^^^^^^^
  File "/Users/macuser/Desktop/django/online_class/venv/lib/python3.11/site-packages/rest_framework/utils/json.py", line 25, in dumps
    return json.dumps(*args, **kwargs)
           ^^^^^^^^^^^^^^^^^^^^^^^^^^^
  File "/usr/local/Cellar/python@3.11/3.11.6_1/Frameworks/Python.framework/Versions/3.11/lib/python3.11/json/__init__.py", line 238, in dumps
    **kw).encode(obj)
          ^^^^^^^^^^^
  File "/usr/local/Cellar/python@3.11/3.11.6_1/Frameworks/Python.framework/Versions/3.11/lib/python3.11/json/encoder.py", line 200, in encode
    chunks = self.iterencode(o, _one_shot=True)
             ^^^^^^^^^^^^^^^^^^^^^^^^^^^^^^^^^^
  File "/usr/local/Cellar/python@3.11/3.11.6_1/Frameworks/Python.framework/Versions/3.11/lib/python3.11/json/encoder.py", line 258, in iterencode
    return _iterencode(o, 0)
           ^^^^^^^^^^^^^^^^^
  File "/Users/macuser/Desktop/django/online_class/venv/lib/python3.11/site-packages/rest_framework/utils/encoders.py", line 67, in default
    return super().default(obj)
           ^^^^^^^^^^^^^^^^^^^^
  File "/usr/local/Cellar/python@3.11/3.11.6_1/Frameworks/Python.framework/Versions/3.11/lib/python3.11/json/encoder.py", line 180, in default
    raise TypeError(f'Object of type {o.__class__.__name__} '
TypeError: Object of type Response is not JSON serializable
[35;1mHTTP GET /api/classes/class/8ca5ca65-bd20-454c-b583-ad2bbd94ef27/message/197fb606-fb6c-476f-bc99-0575eabd15c3/ 500 [0.11, 127.0.0.1:57661][0m
Internal Server Error: /api/classes/class/8ca5ca65-bd20-454c-b583-ad2bbd94ef27/message/197fb606-fb6c-476f-bc99-0575eabd15c3/
Traceback (most recent call last):
  File "/Users/macuser/Desktop/django/online_class/venv/lib/python3.11/site-packages/asgiref/sync.py", line 534, in thread_handler
    raise exc_info[1]
  File "/Users/macuser/Desktop/django/online_class/venv/lib/python3.11/site-packages/django/core/handlers/exception.py", line 42, in inner
    response = await get_response(request)
               ^^^^^^^^^^^^^^^^^^^^^^^^^^^
  File "/Users/macuser/Desktop/django/online_class/venv/lib/python3.11/site-packages/asgiref/sync.py", line 534, in thread_handler
    raise exc_info[1]
  File "/Users/macuser/Desktop/django/online_class/venv/lib/python3.11/site-packages/django/core/handlers/base.py", line 284, in _get_response_async
    response = await sync_to_async(
               ^^^^^^^^^^^^^^^^^^^^
  File "/Users/macuser/Desktop/django/online_class/venv/lib/python3.11/site-packages/asgiref/sync.py", line 479, in __call__
    ret: _R = await loop.run_in_executor(
              ^^^^^^^^^^^^^^^^^^^^^^^^^^^
  File "/usr/local/Cellar/python@3.11/3.11.6_1/Frameworks/Python.framework/Versions/3.11/lib/python3.11/concurrent/futures/thread.py", line 58, in run
    result = self.fn(*self.args, **self.kwargs)
             ^^^^^^^^^^^^^^^^^^^^^^^^^^^^^^^^^^
  File "/Users/macuser/Desktop/django/online_class/venv/lib/python3.11/site-packages/asgiref/sync.py", line 538, in thread_handler
    return func(*args, **kwargs)
           ^^^^^^^^^^^^^^^^^^^^^
  File "/Users/macuser/Desktop/django/online_class/venv/lib/python3.11/site-packages/django/template/response.py", line 114, in render
    self.content = self.rendered_content
                   ^^^^^^^^^^^^^^^^^^^^^
  File "/Users/macuser/Desktop/django/online_class/venv/lib/python3.11/site-packages/rest_framework/response.py", line 70, in rendered_content
    ret = renderer.render(self.data, accepted_media_type, context)
          ^^^^^^^^^^^^^^^^^^^^^^^^^^^^^^^^^^^^^^^^^^^^^^^^^^^^^^^^
  File "/Users/macuser/Desktop/django/online_class/venv/lib/python3.11/site-packages/rest_framework/renderers.py", line 99, in render
    ret = json.dumps(
          ^^^^^^^^^^^
  File "/Users/macuser/Desktop/django/online_class/venv/lib/python3.11/site-packages/rest_framework/utils/json.py", line 25, in dumps
    return json.dumps(*args, **kwargs)
           ^^^^^^^^^^^^^^^^^^^^^^^^^^^
  File "/usr/local/Cellar/python@3.11/3.11.6_1/Frameworks/Python.framework/Versions/3.11/lib/python3.11/json/__init__.py", line 238, in dumps
    **kw).encode(obj)
          ^^^^^^^^^^^
  File "/usr/local/Cellar/python@3.11/3.11.6_1/Frameworks/Python.framework/Versions/3.11/lib/python3.11/json/encoder.py", line 200, in encode
    chunks = self.iterencode(o, _one_shot=True)
             ^^^^^^^^^^^^^^^^^^^^^^^^^^^^^^^^^^
  File "/usr/local/Cellar/python@3.11/3.11.6_1/Frameworks/Python.framework/Versions/3.11/lib/python3.11/json/encoder.py", line 258, in iterencode
    return _iterencode(o, 0)
           ^^^^^^^^^^^^^^^^^
  File "/Users/macuser/Desktop/django/online_class/venv/lib/python3.11/site-packages/rest_framework/utils/encoders.py", line 67, in default
    return super().default(obj)
           ^^^^^^^^^^^^^^^^^^^^
  File "/usr/local/Cellar/python@3.11/3.11.6_1/Frameworks/Python.framework/Versions/3.11/lib/python3.11/json/encoder.py", line 180, in default
    raise TypeError(f'Object of type {o.__class__.__name__} '
TypeError: Object of type Response is not JSON serializable
[35;1mHTTP GET /api/classes/class/8ca5ca65-bd20-454c-b583-ad2bbd94ef27/message/197fb606-fb6c-476f-bc99-0575eabd15c3/ 500 [0.07, 127.0.0.1:57661][0m
Internal Server Error: /api/classes/class/8ca5ca65-bd20-454c-b583-ad2bbd94ef27/message/197fb606-fb6c-476f-bc99-0575eabd15c3/
Traceback (most recent call last):
  File "/Users/macuser/Desktop/django/online_class/venv/lib/python3.11/site-packages/asgiref/sync.py", line 534, in thread_handler
    raise exc_info[1]
  File "/Users/macuser/Desktop/django/online_class/venv/lib/python3.11/site-packages/django/core/handlers/exception.py", line 42, in inner
    response = await get_response(request)
               ^^^^^^^^^^^^^^^^^^^^^^^^^^^
  File "/Users/macuser/Desktop/django/online_class/venv/lib/python3.11/site-packages/asgiref/sync.py", line 534, in thread_handler
    raise exc_info[1]
  File "/Users/macuser/Desktop/django/online_class/venv/lib/python3.11/site-packages/django/core/handlers/base.py", line 253, in _get_response_async
    response = await wrapped_callback(
               ^^^^^^^^^^^^^^^^^^^^^^^
  File "/Users/macuser/Desktop/django/online_class/venv/lib/python3.11/site-packages/asgiref/sync.py", line 479, in __call__
    ret: _R = await loop.run_in_executor(
              ^^^^^^^^^^^^^^^^^^^^^^^^^^^
  File "/usr/local/Cellar/python@3.11/3.11.6_1/Frameworks/Python.framework/Versions/3.11/lib/python3.11/concurrent/futures/thread.py", line 58, in run
    result = self.fn(*self.args, **self.kwargs)
             ^^^^^^^^^^^^^^^^^^^^^^^^^^^^^^^^^^
  File "/Users/macuser/Desktop/django/online_class/venv/lib/python3.11/site-packages/asgiref/sync.py", line 538, in thread_handler
    return func(*args, **kwargs)
           ^^^^^^^^^^^^^^^^^^^^^
  File "/Users/macuser/Desktop/django/online_class/venv/lib/python3.11/site-packages/django/views/decorators/csrf.py", line 65, in _view_wrapper
    return view_func(request, *args, **kwargs)
           ^^^^^^^^^^^^^^^^^^^^^^^^^^^^^^^^^^^
  File "/Users/macuser/Desktop/django/online_class/venv/lib/python3.11/site-packages/django/views/generic/base.py", line 104, in view
    return self.dispatch(request, *args, **kwargs)
           ^^^^^^^^^^^^^^^^^^^^^^^^^^^^^^^^^^^^^^^
  File "/Users/macuser/Desktop/django/online_class/venv/lib/python3.11/site-packages/rest_framework/views.py", line 509, in dispatch
    response = self.handle_exception(exc)
               ^^^^^^^^^^^^^^^^^^^^^^^^^^
  File "/Users/macuser/Desktop/django/online_class/venv/lib/python3.11/site-packages/rest_framework/views.py", line 469, in handle_exception
    self.raise_uncaught_exception(exc)
  File "/Users/macuser/Desktop/django/online_class/venv/lib/python3.11/site-packages/rest_framework/views.py", line 480, in raise_uncaught_exception
    raise exc
  File "/Users/macuser/Desktop/django/online_class/venv/lib/python3.11/site-packages/rest_framework/views.py", line 506, in dispatch
    response = handler(request, *args, **kwargs)
               ^^^^^^^^^^^^^^^^^^^^^^^^^^^^^^^^^
  File "/Users/macuser/Desktop/django/online_class/project/classes/views.py", line 96, in put
    updated_message = service.edit_message(message, data)
                      ^^^^^^^^^^^^^^^^^^^^^^^^^^^^^^^^^^^
  File "/Users/macuser/Desktop/django/online_class/project/classes/services/class_service.py", line 91, in edit_message
    updated_message = self.messagesRepository.update(message, **data)
                      ^^^^^^^^^^^^^^^^^^^^^^^^^^^^^^^^^^^^^^^^^^^^^^^
  File "/Users/macuser/Desktop/django/online_class/project/repositories/repository.py", line 24, in update
    instance.save()
    ^^^^^^^^^^^^^
AttributeError: 'ReturnDict' object has no attribute 'save'
[35;1mHTTP PUT /api/classes/class/8ca5ca65-bd20-454c-b583-ad2bbd94ef27/message/197fb606-fb6c-476f-bc99-0575eabd15c3/ 500 [0.10, 127.0.0.1:58041][0m
Internal Server Error: /api/classes/class/8ca5ca65-bd20-454c-b583-ad2bbd94ef27/message/197fb606-fb6c-476f-bc99-0575eabd15c3/
Traceback (most recent call last):
  File "/Users/macuser/Desktop/django/online_class/venv/lib/python3.11/site-packages/asgiref/sync.py", line 534, in thread_handler
    raise exc_info[1]
  File "/Users/macuser/Desktop/django/online_class/venv/lib/python3.11/site-packages/django/core/handlers/exception.py", line 42, in inner
    response = await get_response(request)
               ^^^^^^^^^^^^^^^^^^^^^^^^^^^
  File "/Users/macuser/Desktop/django/online_class/venv/lib/python3.11/site-packages/asgiref/sync.py", line 534, in thread_handler
    raise exc_info[1]
  File "/Users/macuser/Desktop/django/online_class/venv/lib/python3.11/site-packages/django/core/handlers/base.py", line 253, in _get_response_async
    response = await wrapped_callback(
               ^^^^^^^^^^^^^^^^^^^^^^^
  File "/Users/macuser/Desktop/django/online_class/venv/lib/python3.11/site-packages/asgiref/sync.py", line 479, in __call__
    ret: _R = await loop.run_in_executor(
              ^^^^^^^^^^^^^^^^^^^^^^^^^^^
  File "/usr/local/Cellar/python@3.11/3.11.6_1/Frameworks/Python.framework/Versions/3.11/lib/python3.11/concurrent/futures/thread.py", line 58, in run
    result = self.fn(*self.args, **self.kwargs)
             ^^^^^^^^^^^^^^^^^^^^^^^^^^^^^^^^^^
  File "/Users/macuser/Desktop/django/online_class/venv/lib/python3.11/site-packages/asgiref/sync.py", line 538, in thread_handler
    return func(*args, **kwargs)
           ^^^^^^^^^^^^^^^^^^^^^
  File "/Users/macuser/Desktop/django/online_class/venv/lib/python3.11/site-packages/django/views/decorators/csrf.py", line 65, in _view_wrapper
    return view_func(request, *args, **kwargs)
           ^^^^^^^^^^^^^^^^^^^^^^^^^^^^^^^^^^^
  File "/Users/macuser/Desktop/django/online_class/venv/lib/python3.11/site-packages/django/views/generic/base.py", line 104, in view
    return self.dispatch(request, *args, **kwargs)
           ^^^^^^^^^^^^^^^^^^^^^^^^^^^^^^^^^^^^^^^
  File "/Users/macuser/Desktop/django/online_class/venv/lib/python3.11/site-packages/rest_framework/views.py", line 509, in dispatch
    response = self.handle_exception(exc)
               ^^^^^^^^^^^^^^^^^^^^^^^^^^
  File "/Users/macuser/Desktop/django/online_class/venv/lib/python3.11/site-packages/rest_framework/views.py", line 469, in handle_exception
    self.raise_uncaught_exception(exc)
  File "/Users/macuser/Desktop/django/online_class/venv/lib/python3.11/site-packages/rest_framework/views.py", line 480, in raise_uncaught_exception
    raise exc
  File "/Users/macuser/Desktop/django/online_class/venv/lib/python3.11/site-packages/rest_framework/views.py", line 506, in dispatch
    response = handler(request, *args, **kwargs)
               ^^^^^^^^^^^^^^^^^^^^^^^^^^^^^^^^^
  File "/Users/macuser/Desktop/django/online_class/project/classes/views.py", line 96, in put
    updated_message = service.edit_message(message, data)
                      ^^^^^^^^^^^^^^^^^^^^^^^^^^^^^^^^^^^
  File "/Users/macuser/Desktop/django/online_class/project/classes/services/class_service.py", line 91, in edit_message
    updated_message = self.messagesRepository.update(message, **data)
                      ^^^^^^^^^^^^^^^^^^^^^^^^^^^^^^^^^^^^^^^^^^^^^^^
TypeError: Repository.update() got an unexpected keyword argument 'edited'
[35;1mHTTP PUT /api/classes/class/8ca5ca65-bd20-454c-b583-ad2bbd94ef27/message/197fb606-fb6c-476f-bc99-0575eabd15c3/ 500 [0.21, 127.0.0.1:58051][0m
Internal Server Error: /api/classes/class/8ca5ca65-bd20-454c-b583-ad2bbd94ef27/message/197fb606-fb6c-476f-bc99-0575eabd15c3/
Traceback (most recent call last):
  File "/Users/macuser/Desktop/django/online_class/venv/lib/python3.11/site-packages/asgiref/sync.py", line 534, in thread_handler
    raise exc_info[1]
  File "/Users/macuser/Desktop/django/online_class/venv/lib/python3.11/site-packages/django/core/handlers/exception.py", line 42, in inner
    response = await get_response(request)
               ^^^^^^^^^^^^^^^^^^^^^^^^^^^
  File "/Users/macuser/Desktop/django/online_class/venv/lib/python3.11/site-packages/asgiref/sync.py", line 534, in thread_handler
    raise exc_info[1]
  File "/Users/macuser/Desktop/django/online_class/venv/lib/python3.11/site-packages/django/core/handlers/base.py", line 253, in _get_response_async
    response = await wrapped_callback(
               ^^^^^^^^^^^^^^^^^^^^^^^
  File "/Users/macuser/Desktop/django/online_class/venv/lib/python3.11/site-packages/asgiref/sync.py", line 479, in __call__
    ret: _R = await loop.run_in_executor(
              ^^^^^^^^^^^^^^^^^^^^^^^^^^^
  File "/usr/local/Cellar/python@3.11/3.11.6_1/Frameworks/Python.framework/Versions/3.11/lib/python3.11/concurrent/futures/thread.py", line 58, in run
    result = self.fn(*self.args, **self.kwargs)
             ^^^^^^^^^^^^^^^^^^^^^^^^^^^^^^^^^^
  File "/Users/macuser/Desktop/django/online_class/venv/lib/python3.11/site-packages/asgiref/sync.py", line 538, in thread_handler
    return func(*args, **kwargs)
           ^^^^^^^^^^^^^^^^^^^^^
  File "/Users/macuser/Desktop/django/online_class/venv/lib/python3.11/site-packages/django/views/decorators/csrf.py", line 65, in _view_wrapper
    return view_func(request, *args, **kwargs)
           ^^^^^^^^^^^^^^^^^^^^^^^^^^^^^^^^^^^
  File "/Users/macuser/Desktop/django/online_class/venv/lib/python3.11/site-packages/django/views/generic/base.py", line 104, in view
    return self.dispatch(request, *args, **kwargs)
           ^^^^^^^^^^^^^^^^^^^^^^^^^^^^^^^^^^^^^^^
  File "/Users/macuser/Desktop/django/online_class/venv/lib/python3.11/site-packages/rest_framework/views.py", line 509, in dispatch
    response = self.handle_exception(exc)
               ^^^^^^^^^^^^^^^^^^^^^^^^^^
  File "/Users/macuser/Desktop/django/online_class/venv/lib/python3.11/site-packages/rest_framework/views.py", line 469, in handle_exception
    self.raise_uncaught_exception(exc)
  File "/Users/macuser/Desktop/django/online_class/venv/lib/python3.11/site-packages/rest_framework/views.py", line 480, in raise_uncaught_exception
    raise exc
  File "/Users/macuser/Desktop/django/online_class/venv/lib/python3.11/site-packages/rest_framework/views.py", line 506, in dispatch
    response = handler(request, *args, **kwargs)
               ^^^^^^^^^^^^^^^^^^^^^^^^^^^^^^^^^
  File "/Users/macuser/Desktop/django/online_class/project/classes/views.py", line 96, in put
    updated_message = service.edit_message(message, data)
                      ^^^^^^^^^^^^^^^^^^^^^^^^^^^^^^^^^^^
  File "/Users/macuser/Desktop/django/online_class/project/classes/services/class_service.py", line 91, in edit_message
    updated_message = self.messagesRepository.update(message, **data)
                      ^^^^^^^^^^^^^^^^^^^^^^^^^^^^^^^^^^^^^^^^^^^^^^^
  File "/Users/macuser/Desktop/django/online_class/project/repositories/repository.py", line 24, in update
    instance.save()
    ^^^^^^^^^^^^^
AttributeError: 'ReturnDict' object has no attribute 'save'
[35;1mHTTP PUT /api/classes/class/8ca5ca65-bd20-454c-b583-ad2bbd94ef27/message/197fb606-fb6c-476f-bc99-0575eabd15c3/ 500 [0.07, 127.0.0.1:58059][0m
Internal Server Error: /api/classes/class/8ca5ca65-bd20-454c-b583-ad2bbd94ef27/message/197fb606-fb6c-476f-bc99-0575eabd15c3/
Traceback (most recent call last):
  File "/Users/macuser/Desktop/django/online_class/venv/lib/python3.11/site-packages/asgiref/sync.py", line 534, in thread_handler
    raise exc_info[1]
  File "/Users/macuser/Desktop/django/online_class/venv/lib/python3.11/site-packages/django/core/handlers/exception.py", line 42, in inner
    response = await get_response(request)
               ^^^^^^^^^^^^^^^^^^^^^^^^^^^
  File "/Users/macuser/Desktop/django/online_class/venv/lib/python3.11/site-packages/asgiref/sync.py", line 534, in thread_handler
    raise exc_info[1]
  File "/Users/macuser/Desktop/django/online_class/venv/lib/python3.11/site-packages/django/core/handlers/base.py", line 253, in _get_response_async
    response = await wrapped_callback(
               ^^^^^^^^^^^^^^^^^^^^^^^
  File "/Users/macuser/Desktop/django/online_class/venv/lib/python3.11/site-packages/asgiref/sync.py", line 479, in __call__
    ret: _R = await loop.run_in_executor(
              ^^^^^^^^^^^^^^^^^^^^^^^^^^^
  File "/usr/local/Cellar/python@3.11/3.11.6_1/Frameworks/Python.framework/Versions/3.11/lib/python3.11/concurrent/futures/thread.py", line 58, in run
    result = self.fn(*self.args, **self.kwargs)
             ^^^^^^^^^^^^^^^^^^^^^^^^^^^^^^^^^^
  File "/Users/macuser/Desktop/django/online_class/venv/lib/python3.11/site-packages/asgiref/sync.py", line 538, in thread_handler
    return func(*args, **kwargs)
           ^^^^^^^^^^^^^^^^^^^^^
  File "/Users/macuser/Desktop/django/online_class/venv/lib/python3.11/site-packages/django/views/decorators/csrf.py", line 65, in _view_wrapper
    return view_func(request, *args, **kwargs)
           ^^^^^^^^^^^^^^^^^^^^^^^^^^^^^^^^^^^
  File "/Users/macuser/Desktop/django/online_class/venv/lib/python3.11/site-packages/django/views/generic/base.py", line 104, in view
    return self.dispatch(request, *args, **kwargs)
           ^^^^^^^^^^^^^^^^^^^^^^^^^^^^^^^^^^^^^^^
  File "/Users/macuser/Desktop/django/online_class/venv/lib/python3.11/site-packages/rest_framework/views.py", line 509, in dispatch
    response = self.handle_exception(exc)
               ^^^^^^^^^^^^^^^^^^^^^^^^^^
  File "/Users/macuser/Desktop/django/online_class/venv/lib/python3.11/site-packages/rest_framework/views.py", line 469, in handle_exception
    self.raise_uncaught_exception(exc)
  File "/Users/macuser/Desktop/django/online_class/venv/lib/python3.11/site-packages/rest_framework/views.py", line 480, in raise_uncaught_exception
    raise exc
  File "/Users/macuser/Desktop/django/online_class/venv/lib/python3.11/site-packages/rest_framework/views.py", line 506, in dispatch
    response = handler(request, *args, **kwargs)
               ^^^^^^^^^^^^^^^^^^^^^^^^^^^^^^^^^
  File "/Users/macuser/Desktop/django/online_class/project/classes/views.py", line 96, in put
    updated_message = service.edit_message(message, data)
                      ^^^^^^^^^^^^^^^^^^^^^^^^^^^^^^^^^^^
  File "/Users/macuser/Desktop/django/online_class/project/classes/services/class_service.py", line 91, in edit_message
    updated_message = self.messagesRepository.update(message, **data)
                      ^^^^^^^^^^^^^^^^^^^^^^^^^^^^^^^^^^^^^^^^^^^^^^^
TypeError: Repository.update() got an unexpected keyword argument 'edited'
[35;1mHTTP PUT /api/classes/class/8ca5ca65-bd20-454c-b583-ad2bbd94ef27/message/197fb606-fb6c-476f-bc99-0575eabd15c3/ 500 [0.11, 127.0.0.1:58068][0m
Internal Server Error: /api/classes/class/8ca5ca65-bd20-454c-b583-ad2bbd94ef27/message/197fb606-fb6c-476f-bc99-0575eabd15c3/
Traceback (most recent call last):
  File "/Users/macuser/Desktop/django/online_class/venv/lib/python3.11/site-packages/asgiref/sync.py", line 534, in thread_handler
    raise exc_info[1]
  File "/Users/macuser/Desktop/django/online_class/venv/lib/python3.11/site-packages/django/core/handlers/exception.py", line 42, in inner
    response = await get_response(request)
               ^^^^^^^^^^^^^^^^^^^^^^^^^^^
  File "/Users/macuser/Desktop/django/online_class/venv/lib/python3.11/site-packages/asgiref/sync.py", line 534, in thread_handler
    raise exc_info[1]
  File "/Users/macuser/Desktop/django/online_class/venv/lib/python3.11/site-packages/django/core/handlers/base.py", line 253, in _get_response_async
    response = await wrapped_callback(
               ^^^^^^^^^^^^^^^^^^^^^^^
  File "/Users/macuser/Desktop/django/online_class/venv/lib/python3.11/site-packages/asgiref/sync.py", line 479, in __call__
    ret: _R = await loop.run_in_executor(
              ^^^^^^^^^^^^^^^^^^^^^^^^^^^
  File "/usr/local/Cellar/python@3.11/3.11.6_1/Frameworks/Python.framework/Versions/3.11/lib/python3.11/concurrent/futures/thread.py", line 58, in run
    result = self.fn(*self.args, **self.kwargs)
             ^^^^^^^^^^^^^^^^^^^^^^^^^^^^^^^^^^
  File "/Users/macuser/Desktop/django/online_class/venv/lib/python3.11/site-packages/asgiref/sync.py", line 538, in thread_handler
    return func(*args, **kwargs)
           ^^^^^^^^^^^^^^^^^^^^^
  File "/Users/macuser/Desktop/django/online_class/venv/lib/python3.11/site-packages/django/views/decorators/csrf.py", line 65, in _view_wrapper
    return view_func(request, *args, **kwargs)
           ^^^^^^^^^^^^^^^^^^^^^^^^^^^^^^^^^^^
  File "/Users/macuser/Desktop/django/online_class/venv/lib/python3.11/site-packages/django/views/generic/base.py", line 104, in view
    return self.dispatch(request, *args, **kwargs)
           ^^^^^^^^^^^^^^^^^^^^^^^^^^^^^^^^^^^^^^^
  File "/Users/macuser/Desktop/django/online_class/venv/lib/python3.11/site-packages/rest_framework/views.py", line 509, in dispatch
    response = self.handle_exception(exc)
               ^^^^^^^^^^^^^^^^^^^^^^^^^^
  File "/Users/macuser/Desktop/django/online_class/venv/lib/python3.11/site-packages/rest_framework/views.py", line 469, in handle_exception
    self.raise_uncaught_exception(exc)
  File "/Users/macuser/Desktop/django/online_class/venv/lib/python3.11/site-packages/rest_framework/views.py", line 480, in raise_uncaught_exception
    raise exc
  File "/Users/macuser/Desktop/django/online_class/venv/lib/python3.11/site-packages/rest_framework/views.py", line 506, in dispatch
    response = handler(request, *args, **kwargs)
               ^^^^^^^^^^^^^^^^^^^^^^^^^^^^^^^^^
  File "/Users/macuser/Desktop/django/online_class/project/classes/views.py", line 96, in put
    updated_message = service.edit_message(message, data)
                      ^^^^^^^^^^^^^^^^^^^^^^^^^^^^^^^^^^^
  File "/Users/macuser/Desktop/django/online_class/project/classes/services/class_service.py", line 91, in edit_message
    updated_message = self.messagesRepository.update(message, **data)
                      ^^^^^^^^^^^^^^^^^^^^^^^^^^^^^^^^^^^^^^^^^^^^^^^
TypeError: Repository.update() got an unexpected keyword argument 'edited'
[35;1mHTTP PUT /api/classes/class/8ca5ca65-bd20-454c-b583-ad2bbd94ef27/message/197fb606-fb6c-476f-bc99-0575eabd15c3/ 500 [0.07, 127.0.0.1:58077][0m
Internal Server Error: /api/classes/class/8ca5ca65-bd20-454c-b583-ad2bbd94ef27/message/197fb606-fb6c-476f-bc99-0575eabd15c3/
Traceback (most recent call last):
  File "/Users/macuser/Desktop/django/online_class/venv/lib/python3.11/site-packages/asgiref/sync.py", line 534, in thread_handler
    raise exc_info[1]
  File "/Users/macuser/Desktop/django/online_class/venv/lib/python3.11/site-packages/django/core/handlers/exception.py", line 42, in inner
    response = await get_response(request)
               ^^^^^^^^^^^^^^^^^^^^^^^^^^^
  File "/Users/macuser/Desktop/django/online_class/venv/lib/python3.11/site-packages/asgiref/sync.py", line 534, in thread_handler
    raise exc_info[1]
  File "/Users/macuser/Desktop/django/online_class/venv/lib/python3.11/site-packages/django/core/handlers/base.py", line 253, in _get_response_async
    response = await wrapped_callback(
               ^^^^^^^^^^^^^^^^^^^^^^^
  File "/Users/macuser/Desktop/django/online_class/venv/lib/python3.11/site-packages/asgiref/sync.py", line 479, in __call__
    ret: _R = await loop.run_in_executor(
              ^^^^^^^^^^^^^^^^^^^^^^^^^^^
  File "/usr/local/Cellar/python@3.11/3.11.6_1/Frameworks/Python.framework/Versions/3.11/lib/python3.11/concurrent/futures/thread.py", line 58, in run
    result = self.fn(*self.args, **self.kwargs)
             ^^^^^^^^^^^^^^^^^^^^^^^^^^^^^^^^^^
  File "/Users/macuser/Desktop/django/online_class/venv/lib/python3.11/site-packages/asgiref/sync.py", line 538, in thread_handler
    return func(*args, **kwargs)
           ^^^^^^^^^^^^^^^^^^^^^
  File "/Users/macuser/Desktop/django/online_class/venv/lib/python3.11/site-packages/django/views/decorators/csrf.py", line 65, in _view_wrapper
    return view_func(request, *args, **kwargs)
           ^^^^^^^^^^^^^^^^^^^^^^^^^^^^^^^^^^^
  File "/Users/macuser/Desktop/django/online_class/venv/lib/python3.11/site-packages/django/views/generic/base.py", line 104, in view
    return self.dispatch(request, *args, **kwargs)
           ^^^^^^^^^^^^^^^^^^^^^^^^^^^^^^^^^^^^^^^
  File "/Users/macuser/Desktop/django/online_class/venv/lib/python3.11/site-packages/rest_framework/views.py", line 509, in dispatch
    response = self.handle_exception(exc)
               ^^^^^^^^^^^^^^^^^^^^^^^^^^
  File "/Users/macuser/Desktop/django/online_class/venv/lib/python3.11/site-packages/rest_framework/views.py", line 469, in handle_exception
    self.raise_uncaught_exception(exc)
  File "/Users/macuser/Desktop/django/online_class/venv/lib/python3.11/site-packages/rest_framework/views.py", line 480, in raise_uncaught_exception
    raise exc
  File "/Users/macuser/Desktop/django/online_class/venv/lib/python3.11/site-packages/rest_framework/views.py", line 506, in dispatch
    response = handler(request, *args, **kwargs)
               ^^^^^^^^^^^^^^^^^^^^^^^^^^^^^^^^^
  File "/Users/macuser/Desktop/django/online_class/project/classes/views.py", line 96, in put
    updated_message = service.edit_message(message, data)
                      ^^^^^^^^^^^^^^^^^^^^^^^^^^^^^^^^^^^
  File "/Users/macuser/Desktop/django/online_class/project/classes/services/class_service.py", line 91, in edit_message
    updated_message = self.messagesRepository.update(message, **data)
                      ^^^^^^^^^^^^^^^^^^^^^^^^^^^^^^^^^^^^^^^^^^^^^^^
  File "/Users/macuser/Desktop/django/online_class/project/repositories/repository.py", line 22, in update
    instance.save()
    ^^^^^^^^^^^^^
AttributeError: 'ReturnDict' object has no attribute 'save'
[35;1mHTTP PUT /api/classes/class/8ca5ca65-bd20-454c-b583-ad2bbd94ef27/message/197fb606-fb6c-476f-bc99-0575eabd15c3/ 500 [0.16, 127.0.0.1:58146][0m
Internal Server Error: /api/classes/class/8ca5ca65-bd20-454c-b583-ad2bbd94ef27/message/197fb606-fb6c-476f-bc99-0575eabd15c3/
Traceback (most recent call last):
  File "/Users/macuser/Desktop/django/online_class/venv/lib/python3.11/site-packages/asgiref/sync.py", line 534, in thread_handler
    raise exc_info[1]
  File "/Users/macuser/Desktop/django/online_class/venv/lib/python3.11/site-packages/django/core/handlers/exception.py", line 42, in inner
    response = await get_response(request)
               ^^^^^^^^^^^^^^^^^^^^^^^^^^^
  File "/Users/macuser/Desktop/django/online_class/venv/lib/python3.11/site-packages/asgiref/sync.py", line 534, in thread_handler
    raise exc_info[1]
  File "/Users/macuser/Desktop/django/online_class/venv/lib/python3.11/site-packages/django/core/handlers/base.py", line 253, in _get_response_async
    response = await wrapped_callback(
               ^^^^^^^^^^^^^^^^^^^^^^^
  File "/Users/macuser/Desktop/django/online_class/venv/lib/python3.11/site-packages/asgiref/sync.py", line 479, in __call__
    ret: _R = await loop.run_in_executor(
              ^^^^^^^^^^^^^^^^^^^^^^^^^^^
  File "/usr/local/Cellar/python@3.11/3.11.6_1/Frameworks/Python.framework/Versions/3.11/lib/python3.11/concurrent/futures/thread.py", line 58, in run
    result = self.fn(*self.args, **self.kwargs)
             ^^^^^^^^^^^^^^^^^^^^^^^^^^^^^^^^^^
  File "/Users/macuser/Desktop/django/online_class/venv/lib/python3.11/site-packages/asgiref/sync.py", line 538, in thread_handler
    return func(*args, **kwargs)
           ^^^^^^^^^^^^^^^^^^^^^
  File "/Users/macuser/Desktop/django/online_class/venv/lib/python3.11/site-packages/django/views/decorators/csrf.py", line 65, in _view_wrapper
    return view_func(request, *args, **kwargs)
           ^^^^^^^^^^^^^^^^^^^^^^^^^^^^^^^^^^^
  File "/Users/macuser/Desktop/django/online_class/venv/lib/python3.11/site-packages/django/views/generic/base.py", line 104, in view
    return self.dispatch(request, *args, **kwargs)
           ^^^^^^^^^^^^^^^^^^^^^^^^^^^^^^^^^^^^^^^
  File "/Users/macuser/Desktop/django/online_class/venv/lib/python3.11/site-packages/rest_framework/views.py", line 509, in dispatch
    response = self.handle_exception(exc)
               ^^^^^^^^^^^^^^^^^^^^^^^^^^
  File "/Users/macuser/Desktop/django/online_class/venv/lib/python3.11/site-packages/rest_framework/views.py", line 469, in handle_exception
    self.raise_uncaught_exception(exc)
  File "/Users/macuser/Desktop/django/online_class/venv/lib/python3.11/site-packages/rest_framework/views.py", line 480, in raise_uncaught_exception
    raise exc
  File "/Users/macuser/Desktop/django/online_class/venv/lib/python3.11/site-packages/rest_framework/views.py", line 506, in dispatch
    response = handler(request, *args, **kwargs)
               ^^^^^^^^^^^^^^^^^^^^^^^^^^^^^^^^^
  File "/Users/macuser/Desktop/django/online_class/project/classes/views.py", line 96, in put
    updated_message = service.edit_message(message, data)
                      ^^^^^^^^^^^^^^^^^^^^^^^^^^^^^^^^^^^
  File "/Users/macuser/Desktop/django/online_class/project/classes/services/class_service.py", line 91, in edit_message
    updated_message = self.messagesRepository.update(message, **data)
                      ^^^^^^^^^^^^^^^^^^^^^^^^^^^^^^^^^^^^^^^^^^^^^^^
  File "/Users/macuser/Desktop/django/online_class/project/repositories/repository.py", line 22, in update
    instance.save()
    ^^^^^^^^^^^^^
AttributeError: 'ReturnDict' object has no attribute 'save'
[35;1mHTTP PUT /api/classes/class/8ca5ca65-bd20-454c-b583-ad2bbd94ef27/message/197fb606-fb6c-476f-bc99-0575eabd15c3/ 500 [0.05, 127.0.0.1:58146][0m
Internal Server Error: /api/classes/class/8ca5ca65-bd20-454c-b583-ad2bbd94ef27/message/197fb606-fb6c-476f-bc99-0575eabd15c3/
Traceback (most recent call last):
  File "/Users/macuser/Desktop/django/online_class/venv/lib/python3.11/site-packages/asgiref/sync.py", line 534, in thread_handler
    raise exc_info[1]
  File "/Users/macuser/Desktop/django/online_class/venv/lib/python3.11/site-packages/django/core/handlers/exception.py", line 42, in inner
    response = await get_response(request)
               ^^^^^^^^^^^^^^^^^^^^^^^^^^^
  File "/Users/macuser/Desktop/django/online_class/venv/lib/python3.11/site-packages/asgiref/sync.py", line 534, in thread_handler
    raise exc_info[1]
  File "/Users/macuser/Desktop/django/online_class/venv/lib/python3.11/site-packages/django/core/handlers/base.py", line 253, in _get_response_async
    response = await wrapped_callback(
               ^^^^^^^^^^^^^^^^^^^^^^^
  File "/Users/macuser/Desktop/django/online_class/venv/lib/python3.11/site-packages/asgiref/sync.py", line 479, in __call__
    ret: _R = await loop.run_in_executor(
              ^^^^^^^^^^^^^^^^^^^^^^^^^^^
  File "/usr/local/Cellar/python@3.11/3.11.6_1/Frameworks/Python.framework/Versions/3.11/lib/python3.11/concurrent/futures/thread.py", line 58, in run
    result = self.fn(*self.args, **self.kwargs)
             ^^^^^^^^^^^^^^^^^^^^^^^^^^^^^^^^^^
  File "/Users/macuser/Desktop/django/online_class/venv/lib/python3.11/site-packages/asgiref/sync.py", line 538, in thread_handler
    return func(*args, **kwargs)
           ^^^^^^^^^^^^^^^^^^^^^
  File "/Users/macuser/Desktop/django/online_class/venv/lib/python3.11/site-packages/django/views/decorators/csrf.py", line 65, in _view_wrapper
    return view_func(request, *args, **kwargs)
           ^^^^^^^^^^^^^^^^^^^^^^^^^^^^^^^^^^^
  File "/Users/macuser/Desktop/django/online_class/venv/lib/python3.11/site-packages/django/views/generic/base.py", line 104, in view
    return self.dispatch(request, *args, **kwargs)
           ^^^^^^^^^^^^^^^^^^^^^^^^^^^^^^^^^^^^^^^
  File "/Users/macuser/Desktop/django/online_class/venv/lib/python3.11/site-packages/rest_framework/views.py", line 509, in dispatch
    response = self.handle_exception(exc)
               ^^^^^^^^^^^^^^^^^^^^^^^^^^
  File "/Users/macuser/Desktop/django/online_class/venv/lib/python3.11/site-packages/rest_framework/views.py", line 469, in handle_exception
    self.raise_uncaught_exception(exc)
  File "/Users/macuser/Desktop/django/online_class/venv/lib/python3.11/site-packages/rest_framework/views.py", line 480, in raise_uncaught_exception
    raise exc
  File "/Users/macuser/Desktop/django/online_class/venv/lib/python3.11/site-packages/rest_framework/views.py", line 506, in dispatch
    response = handler(request, *args, **kwargs)
               ^^^^^^^^^^^^^^^^^^^^^^^^^^^^^^^^^
  File "/Users/macuser/Desktop/django/online_class/project/classes/views.py", line 96, in put
    updated_message = service.edit_message(message, data)
                      ^^^^^^^^^^^^^^^^^^^^^^^^^^^^^^^^^^^
  File "/Users/macuser/Desktop/django/online_class/project/classes/services/class_service.py", line 91, in edit_message
    updated_message = self.messagesRepository.update(message, **data)
                      ^^^^^^^^^^^^^^^^^^^^^^^^^^^^^^^^^^^^^^^^^^^^^^^
TypeError: Repository.update() got an unexpected keyword argument 'edited'
[35;1mHTTP PUT /api/classes/class/8ca5ca65-bd20-454c-b583-ad2bbd94ef27/message/197fb606-fb6c-476f-bc99-0575eabd15c3/ 500 [0.10, 127.0.0.1:58154][0m
Internal Server Error: /api/classes/class/8ca5ca65-bd20-454c-b583-ad2bbd94ef27/message/197fb606-fb6c-476f-bc99-0575eabd15c3/
Traceback (most recent call last):
  File "/Users/macuser/Desktop/django/online_class/venv/lib/python3.11/site-packages/asgiref/sync.py", line 534, in thread_handler
    raise exc_info[1]
  File "/Users/macuser/Desktop/django/online_class/venv/lib/python3.11/site-packages/django/core/handlers/exception.py", line 42, in inner
    response = await get_response(request)
               ^^^^^^^^^^^^^^^^^^^^^^^^^^^
  File "/Users/macuser/Desktop/django/online_class/venv/lib/python3.11/site-packages/asgiref/sync.py", line 534, in thread_handler
    raise exc_info[1]
  File "/Users/macuser/Desktop/django/online_class/venv/lib/python3.11/site-packages/django/core/handlers/base.py", line 253, in _get_response_async
    response = await wrapped_callback(
               ^^^^^^^^^^^^^^^^^^^^^^^
  File "/Users/macuser/Desktop/django/online_class/venv/lib/python3.11/site-packages/asgiref/sync.py", line 479, in __call__
    ret: _R = await loop.run_in_executor(
              ^^^^^^^^^^^^^^^^^^^^^^^^^^^
  File "/usr/local/Cellar/python@3.11/3.11.6_1/Frameworks/Python.framework/Versions/3.11/lib/python3.11/concurrent/futures/thread.py", line 58, in run
    result = self.fn(*self.args, **self.kwargs)
             ^^^^^^^^^^^^^^^^^^^^^^^^^^^^^^^^^^
  File "/Users/macuser/Desktop/django/online_class/venv/lib/python3.11/site-packages/asgiref/sync.py", line 538, in thread_handler
    return func(*args, **kwargs)
           ^^^^^^^^^^^^^^^^^^^^^
  File "/Users/macuser/Desktop/django/online_class/venv/lib/python3.11/site-packages/django/views/decorators/csrf.py", line 65, in _view_wrapper
    return view_func(request, *args, **kwargs)
           ^^^^^^^^^^^^^^^^^^^^^^^^^^^^^^^^^^^
  File "/Users/macuser/Desktop/django/online_class/venv/lib/python3.11/site-packages/django/views/generic/base.py", line 104, in view
    return self.dispatch(request, *args, **kwargs)
           ^^^^^^^^^^^^^^^^^^^^^^^^^^^^^^^^^^^^^^^
  File "/Users/macuser/Desktop/django/online_class/venv/lib/python3.11/site-packages/rest_framework/views.py", line 509, in dispatch
    response = self.handle_exception(exc)
               ^^^^^^^^^^^^^^^^^^^^^^^^^^
  File "/Users/macuser/Desktop/django/online_class/venv/lib/python3.11/site-packages/rest_framework/views.py", line 469, in handle_exception
    self.raise_uncaught_exception(exc)
  File "/Users/macuser/Desktop/django/online_class/venv/lib/python3.11/site-packages/rest_framework/views.py", line 480, in raise_uncaught_exception
    raise exc
  File "/Users/macuser/Desktop/django/online_class/venv/lib/python3.11/site-packages/rest_framework/views.py", line 506, in dispatch
    response = handler(request, *args, **kwargs)
               ^^^^^^^^^^^^^^^^^^^^^^^^^^^^^^^^^
  File "/Users/macuser/Desktop/django/online_class/project/classes/views.py", line 96, in put
    updated_message = service.edit_message(message, data)
                      ^^^^^^^^^^^^^^^^^^^^^^^^^^^^^^^^^^^
  File "/Users/macuser/Desktop/django/online_class/project/classes/services/class_service.py", line 91, in edit_message
    updated_message = self.messagesRepository.update(message, **data)
                      ^^^^^^^^^^^^^^^^^^^^^^^^^^^^^^^^^^^^^^^^^^^^^^^
TypeError: Repository.update() got an unexpected keyword argument 'edited'
[35;1mHTTP PUT /api/classes/class/8ca5ca65-bd20-454c-b583-ad2bbd94ef27/message/197fb606-fb6c-476f-bc99-0575eabd15c3/ 500 [0.08, 127.0.0.1:58159][0m
Internal Server Error: /api/classes/class/8ca5ca65-bd20-454c-b583-ad2bbd94ef27/message/197fb606-fb6c-476f-bc99-0575eabd15c3/
Traceback (most recent call last):
  File "/Users/macuser/Desktop/django/online_class/venv/lib/python3.11/site-packages/asgiref/sync.py", line 534, in thread_handler
    raise exc_info[1]
  File "/Users/macuser/Desktop/django/online_class/venv/lib/python3.11/site-packages/django/core/handlers/exception.py", line 42, in inner
    response = await get_response(request)
               ^^^^^^^^^^^^^^^^^^^^^^^^^^^
  File "/Users/macuser/Desktop/django/online_class/venv/lib/python3.11/site-packages/asgiref/sync.py", line 534, in thread_handler
    raise exc_info[1]
  File "/Users/macuser/Desktop/django/online_class/venv/lib/python3.11/site-packages/django/core/handlers/base.py", line 253, in _get_response_async
    response = await wrapped_callback(
               ^^^^^^^^^^^^^^^^^^^^^^^
  File "/Users/macuser/Desktop/django/online_class/venv/lib/python3.11/site-packages/asgiref/sync.py", line 479, in __call__
    ret: _R = await loop.run_in_executor(
              ^^^^^^^^^^^^^^^^^^^^^^^^^^^
  File "/usr/local/Cellar/python@3.11/3.11.6_1/Frameworks/Python.framework/Versions/3.11/lib/python3.11/concurrent/futures/thread.py", line 58, in run
    result = self.fn(*self.args, **self.kwargs)
             ^^^^^^^^^^^^^^^^^^^^^^^^^^^^^^^^^^
  File "/Users/macuser/Desktop/django/online_class/venv/lib/python3.11/site-packages/asgiref/sync.py", line 538, in thread_handler
    return func(*args, **kwargs)
           ^^^^^^^^^^^^^^^^^^^^^
  File "/Users/macuser/Desktop/django/online_class/venv/lib/python3.11/site-packages/django/views/decorators/csrf.py", line 65, in _view_wrapper
    return view_func(request, *args, **kwargs)
           ^^^^^^^^^^^^^^^^^^^^^^^^^^^^^^^^^^^
  File "/Users/macuser/Desktop/django/online_class/venv/lib/python3.11/site-packages/django/views/generic/base.py", line 104, in view
    return self.dispatch(request, *args, **kwargs)
           ^^^^^^^^^^^^^^^^^^^^^^^^^^^^^^^^^^^^^^^
  File "/Users/macuser/Desktop/django/online_class/venv/lib/python3.11/site-packages/rest_framework/views.py", line 509, in dispatch
    response = self.handle_exception(exc)
               ^^^^^^^^^^^^^^^^^^^^^^^^^^
  File "/Users/macuser/Desktop/django/online_class/venv/lib/python3.11/site-packages/rest_framework/views.py", line 469, in handle_exception
    self.raise_uncaught_exception(exc)
  File "/Users/macuser/Desktop/django/online_class/venv/lib/python3.11/site-packages/rest_framework/views.py", line 480, in raise_uncaught_exception
    raise exc
  File "/Users/macuser/Desktop/django/online_class/venv/lib/python3.11/site-packages/rest_framework/views.py", line 506, in dispatch
    response = handler(request, *args, **kwargs)
               ^^^^^^^^^^^^^^^^^^^^^^^^^^^^^^^^^
  File "/Users/macuser/Desktop/django/online_class/project/classes/views.py", line 96, in put
    updated_message = service.edit_message(message, data)
                      ^^^^^^^^^^^^^^^^^^^^^^^^^^^^^^^^^^^
  File "/Users/macuser/Desktop/django/online_class/project/classes/services/class_service.py", line 91, in edit_message
    updated_message = self.messagesRepository.update(message, **data)
                      ^^^^^^^^^^^^^^^^^^^^^^^^^^^^^^^^^^^^^^^^^^^^^^^
TypeError: Repository.update() got an unexpected keyword argument 'edited'
[35;1mHTTP PUT /api/classes/class/8ca5ca65-bd20-454c-b583-ad2bbd94ef27/message/197fb606-fb6c-476f-bc99-0575eabd15c3/ 500 [0.06, 127.0.0.1:58159][0m
Internal Server Error: /api/classes/class/8ca5ca65-bd20-454c-b583-ad2bbd94ef27/message/197fb606-fb6c-476f-bc99-0575eabd15c3/
Traceback (most recent call last):
  File "/Users/macuser/Desktop/django/online_class/venv/lib/python3.11/site-packages/asgiref/sync.py", line 534, in thread_handler
    raise exc_info[1]
  File "/Users/macuser/Desktop/django/online_class/venv/lib/python3.11/site-packages/django/core/handlers/exception.py", line 42, in inner
    response = await get_response(request)
               ^^^^^^^^^^^^^^^^^^^^^^^^^^^
  File "/Users/macuser/Desktop/django/online_class/venv/lib/python3.11/site-packages/asgiref/sync.py", line 534, in thread_handler
    raise exc_info[1]
  File "/Users/macuser/Desktop/django/online_class/venv/lib/python3.11/site-packages/django/core/handlers/base.py", line 253, in _get_response_async
    response = await wrapped_callback(
               ^^^^^^^^^^^^^^^^^^^^^^^
  File "/Users/macuser/Desktop/django/online_class/venv/lib/python3.11/site-packages/asgiref/sync.py", line 479, in __call__
    ret: _R = await loop.run_in_executor(
              ^^^^^^^^^^^^^^^^^^^^^^^^^^^
  File "/usr/local/Cellar/python@3.11/3.11.6_1/Frameworks/Python.framework/Versions/3.11/lib/python3.11/concurrent/futures/thread.py", line 58, in run
    result = self.fn(*self.args, **self.kwargs)
             ^^^^^^^^^^^^^^^^^^^^^^^^^^^^^^^^^^
  File "/Users/macuser/Desktop/django/online_class/venv/lib/python3.11/site-packages/asgiref/sync.py", line 538, in thread_handler
    return func(*args, **kwargs)
           ^^^^^^^^^^^^^^^^^^^^^
  File "/Users/macuser/Desktop/django/online_class/venv/lib/python3.11/site-packages/django/views/decorators/csrf.py", line 65, in _view_wrapper
    return view_func(request, *args, **kwargs)
           ^^^^^^^^^^^^^^^^^^^^^^^^^^^^^^^^^^^
  File "/Users/macuser/Desktop/django/online_class/venv/lib/python3.11/site-packages/django/views/generic/base.py", line 104, in view
    return self.dispatch(request, *args, **kwargs)
           ^^^^^^^^^^^^^^^^^^^^^^^^^^^^^^^^^^^^^^^
  File "/Users/macuser/Desktop/django/online_class/venv/lib/python3.11/site-packages/rest_framework/views.py", line 509, in dispatch
    response = self.handle_exception(exc)
               ^^^^^^^^^^^^^^^^^^^^^^^^^^
  File "/Users/macuser/Desktop/django/online_class/venv/lib/python3.11/site-packages/rest_framework/views.py", line 469, in handle_exception
    self.raise_uncaught_exception(exc)
  File "/Users/macuser/Desktop/django/online_class/venv/lib/python3.11/site-packages/rest_framework/views.py", line 480, in raise_uncaught_exception
    raise exc
  File "/Users/macuser/Desktop/django/online_class/venv/lib/python3.11/site-packages/rest_framework/views.py", line 506, in dispatch
    response = handler(request, *args, **kwargs)
               ^^^^^^^^^^^^^^^^^^^^^^^^^^^^^^^^^
  File "/Users/macuser/Desktop/django/online_class/project/classes/views.py", line 96, in put
    updated_message = service.edit_message(message, data)
                      ^^^^^^^^^^^^^^^^^^^^^^^^^^^^^^^^^^^
  File "/Users/macuser/Desktop/django/online_class/project/classes/services/class_service.py", line 91, in edit_message
    updated_message = self.messagesRepository.update(message, **data)
                      ^^^^^^^^^^^^^^^^^^^^^^^^^^^^^^^^^^^^^^^^^^^^^^^
TypeError: Repository.update() got an unexpected keyword argument 'edited'
[35;1mHTTP PUT /api/classes/class/8ca5ca65-bd20-454c-b583-ad2bbd94ef27/message/197fb606-fb6c-476f-bc99-0575eabd15c3/ 500 [0.04, 127.0.0.1:58159][0m
Internal Server Error: /api/classes/class/8ca5ca65-bd20-454c-b583-ad2bbd94ef27/message/197fb606-fb6c-476f-bc99-0575eabd15c3/
Traceback (most recent call last):
  File "/Users/macuser/Desktop/django/online_class/venv/lib/python3.11/site-packages/asgiref/sync.py", line 534, in thread_handler
    raise exc_info[1]
  File "/Users/macuser/Desktop/django/online_class/venv/lib/python3.11/site-packages/django/core/handlers/exception.py", line 42, in inner
    response = await get_response(request)
               ^^^^^^^^^^^^^^^^^^^^^^^^^^^
  File "/Users/macuser/Desktop/django/online_class/venv/lib/python3.11/site-packages/asgiref/sync.py", line 534, in thread_handler
    raise exc_info[1]
  File "/Users/macuser/Desktop/django/online_class/venv/lib/python3.11/site-packages/django/core/handlers/base.py", line 253, in _get_response_async
    response = await wrapped_callback(
               ^^^^^^^^^^^^^^^^^^^^^^^
  File "/Users/macuser/Desktop/django/online_class/venv/lib/python3.11/site-packages/asgiref/sync.py", line 479, in __call__
    ret: _R = await loop.run_in_executor(
              ^^^^^^^^^^^^^^^^^^^^^^^^^^^
  File "/usr/local/Cellar/python@3.11/3.11.6_1/Frameworks/Python.framework/Versions/3.11/lib/python3.11/concurrent/futures/thread.py", line 58, in run
    result = self.fn(*self.args, **self.kwargs)
             ^^^^^^^^^^^^^^^^^^^^^^^^^^^^^^^^^^
  File "/Users/macuser/Desktop/django/online_class/venv/lib/python3.11/site-packages/asgiref/sync.py", line 538, in thread_handler
    return func(*args, **kwargs)
           ^^^^^^^^^^^^^^^^^^^^^
  File "/Users/macuser/Desktop/django/online_class/venv/lib/python3.11/site-packages/django/views/decorators/csrf.py", line 65, in _view_wrapper
    return view_func(request, *args, **kwargs)
           ^^^^^^^^^^^^^^^^^^^^^^^^^^^^^^^^^^^
  File "/Users/macuser/Desktop/django/online_class/venv/lib/python3.11/site-packages/django/views/generic/base.py", line 104, in view
    return self.dispatch(request, *args, **kwargs)
           ^^^^^^^^^^^^^^^^^^^^^^^^^^^^^^^^^^^^^^^
  File "/Users/macuser/Desktop/django/online_class/venv/lib/python3.11/site-packages/rest_framework/views.py", line 509, in dispatch
    response = self.handle_exception(exc)
               ^^^^^^^^^^^^^^^^^^^^^^^^^^
  File "/Users/macuser/Desktop/django/online_class/venv/lib/python3.11/site-packages/rest_framework/views.py", line 469, in handle_exception
    self.raise_uncaught_exception(exc)
  File "/Users/macuser/Desktop/django/online_class/venv/lib/python3.11/site-packages/rest_framework/views.py", line 480, in raise_uncaught_exception
    raise exc
  File "/Users/macuser/Desktop/django/online_class/venv/lib/python3.11/site-packages/rest_framework/views.py", line 506, in dispatch
    response = handler(request, *args, **kwargs)
               ^^^^^^^^^^^^^^^^^^^^^^^^^^^^^^^^^
  File "/Users/macuser/Desktop/django/online_class/project/classes/views.py", line 96, in put
    updated_message = service.edit_message(message, data)
                      ^^^^^^^^^^^^^^^^^^^^^^^^^^^^^^^^^^^
  File "/Users/macuser/Desktop/django/online_class/project/classes/services/class_service.py", line 91, in edit_message
    updated_message = self.messagesRepository.update(message, **data)
                      ^^^^^^^^^^^^^^^^^^^^^^^^^^^^^^^^^^^^^^^^^^^^^^^
TypeError: Repository.update() got an unexpected keyword argument 'edited'
[35;1mHTTP PUT /api/classes/class/8ca5ca65-bd20-454c-b583-ad2bbd94ef27/message/197fb606-fb6c-476f-bc99-0575eabd15c3/ 500 [0.18, 127.0.0.1:58172][0m
Internal Server Error: /api/classes/class/8ca5ca65-bd20-454c-b583-ad2bbd94ef27/message/197fb606-fb6c-476f-bc99-0575eabd15c3/
Traceback (most recent call last):
  File "/Users/macuser/Desktop/django/online_class/venv/lib/python3.11/site-packages/asgiref/sync.py", line 534, in thread_handler
    raise exc_info[1]
  File "/Users/macuser/Desktop/django/online_class/venv/lib/python3.11/site-packages/django/core/handlers/exception.py", line 42, in inner
    response = await get_response(request)
               ^^^^^^^^^^^^^^^^^^^^^^^^^^^
  File "/Users/macuser/Desktop/django/online_class/venv/lib/python3.11/site-packages/asgiref/sync.py", line 534, in thread_handler
    raise exc_info[1]
  File "/Users/macuser/Desktop/django/online_class/venv/lib/python3.11/site-packages/django/core/handlers/base.py", line 253, in _get_response_async
    response = await wrapped_callback(
               ^^^^^^^^^^^^^^^^^^^^^^^
  File "/Users/macuser/Desktop/django/online_class/venv/lib/python3.11/site-packages/asgiref/sync.py", line 479, in __call__
    ret: _R = await loop.run_in_executor(
              ^^^^^^^^^^^^^^^^^^^^^^^^^^^
  File "/usr/local/Cellar/python@3.11/3.11.6_1/Frameworks/Python.framework/Versions/3.11/lib/python3.11/concurrent/futures/thread.py", line 58, in run
    result = self.fn(*self.args, **self.kwargs)
             ^^^^^^^^^^^^^^^^^^^^^^^^^^^^^^^^^^
  File "/Users/macuser/Desktop/django/online_class/venv/lib/python3.11/site-packages/asgiref/sync.py", line 538, in thread_handler
    return func(*args, **kwargs)
           ^^^^^^^^^^^^^^^^^^^^^
  File "/Users/macuser/Desktop/django/online_class/venv/lib/python3.11/site-packages/django/views/decorators/csrf.py", line 65, in _view_wrapper
    return view_func(request, *args, **kwargs)
           ^^^^^^^^^^^^^^^^^^^^^^^^^^^^^^^^^^^
  File "/Users/macuser/Desktop/django/online_class/venv/lib/python3.11/site-packages/django/views/generic/base.py", line 104, in view
    return self.dispatch(request, *args, **kwargs)
           ^^^^^^^^^^^^^^^^^^^^^^^^^^^^^^^^^^^^^^^
  File "/Users/macuser/Desktop/django/online_class/venv/lib/python3.11/site-packages/rest_framework/views.py", line 509, in dispatch
    response = self.handle_exception(exc)
               ^^^^^^^^^^^^^^^^^^^^^^^^^^
  File "/Users/macuser/Desktop/django/online_class/venv/lib/python3.11/site-packages/rest_framework/views.py", line 469, in handle_exception
    self.raise_uncaught_exception(exc)
  File "/Users/macuser/Desktop/django/online_class/venv/lib/python3.11/site-packages/rest_framework/views.py", line 480, in raise_uncaught_exception
    raise exc
  File "/Users/macuser/Desktop/django/online_class/venv/lib/python3.11/site-packages/rest_framework/views.py", line 506, in dispatch
    response = handler(request, *args, **kwargs)
               ^^^^^^^^^^^^^^^^^^^^^^^^^^^^^^^^^
  File "/Users/macuser/Desktop/django/online_class/project/classes/views.py", line 96, in put
    updated_message = service.edit_message(message, data)
                      ^^^^^^^^^^^^^^^^^^^^^^^^^^^^^^^^^^^
  File "/Users/macuser/Desktop/django/online_class/project/classes/services/class_service.py", line 91, in edit_message
    updated_message = self.messagesRepository.update(message, **data)
                      ^^^^^^^^^^^^^^^^^^^^^^^^^^^^^^^^^^^^^^^^^^^^^^^
TypeError: Repository.update() got an unexpected keyword argument 'edited'
[35;1mHTTP PUT /api/classes/class/8ca5ca65-bd20-454c-b583-ad2bbd94ef27/message/197fb606-fb6c-476f-bc99-0575eabd15c3/ 500 [0.05, 127.0.0.1:58172][0m
Internal Server Error: /api/classes/class/8ca5ca65-bd20-454c-b583-ad2bbd94ef27/message/197fb606-fb6c-476f-bc99-0575eabd15c3/
Traceback (most recent call last):
  File "/Users/macuser/Desktop/django/online_class/venv/lib/python3.11/site-packages/asgiref/sync.py", line 534, in thread_handler
    raise exc_info[1]
  File "/Users/macuser/Desktop/django/online_class/venv/lib/python3.11/site-packages/django/core/handlers/exception.py", line 42, in inner
    response = await get_response(request)
               ^^^^^^^^^^^^^^^^^^^^^^^^^^^
  File "/Users/macuser/Desktop/django/online_class/venv/lib/python3.11/site-packages/asgiref/sync.py", line 534, in thread_handler
    raise exc_info[1]
  File "/Users/macuser/Desktop/django/online_class/venv/lib/python3.11/site-packages/django/core/handlers/base.py", line 253, in _get_response_async
    response = await wrapped_callback(
               ^^^^^^^^^^^^^^^^^^^^^^^
  File "/Users/macuser/Desktop/django/online_class/venv/lib/python3.11/site-packages/asgiref/sync.py", line 479, in __call__
    ret: _R = await loop.run_in_executor(
              ^^^^^^^^^^^^^^^^^^^^^^^^^^^
  File "/usr/local/Cellar/python@3.11/3.11.6_1/Frameworks/Python.framework/Versions/3.11/lib/python3.11/concurrent/futures/thread.py", line 58, in run
    result = self.fn(*self.args, **self.kwargs)
             ^^^^^^^^^^^^^^^^^^^^^^^^^^^^^^^^^^
  File "/Users/macuser/Desktop/django/online_class/venv/lib/python3.11/site-packages/asgiref/sync.py", line 538, in thread_handler
    return func(*args, **kwargs)
           ^^^^^^^^^^^^^^^^^^^^^
  File "/Users/macuser/Desktop/django/online_class/venv/lib/python3.11/site-packages/django/views/decorators/csrf.py", line 65, in _view_wrapper
    return view_func(request, *args, **kwargs)
           ^^^^^^^^^^^^^^^^^^^^^^^^^^^^^^^^^^^
  File "/Users/macuser/Desktop/django/online_class/venv/lib/python3.11/site-packages/django/views/generic/base.py", line 104, in view
    return self.dispatch(request, *args, **kwargs)
           ^^^^^^^^^^^^^^^^^^^^^^^^^^^^^^^^^^^^^^^
  File "/Users/macuser/Desktop/django/online_class/venv/lib/python3.11/site-packages/rest_framework/views.py", line 509, in dispatch
    response = self.handle_exception(exc)
               ^^^^^^^^^^^^^^^^^^^^^^^^^^
  File "/Users/macuser/Desktop/django/online_class/venv/lib/python3.11/site-packages/rest_framework/views.py", line 469, in handle_exception
    self.raise_uncaught_exception(exc)
  File "/Users/macuser/Desktop/django/online_class/venv/lib/python3.11/site-packages/rest_framework/views.py", line 480, in raise_uncaught_exception
    raise exc
  File "/Users/macuser/Desktop/django/online_class/venv/lib/python3.11/site-packages/rest_framework/views.py", line 506, in dispatch
    response = handler(request, *args, **kwargs)
               ^^^^^^^^^^^^^^^^^^^^^^^^^^^^^^^^^
  File "/Users/macuser/Desktop/django/online_class/project/classes/views.py", line 96, in put
    updated_message = service.edit_message(message, data)
                      ^^^^^^^^^^^^^^^^^^^^^^^^^^^^^^^^^^^
  File "/Users/macuser/Desktop/django/online_class/project/classes/services/class_service.py", line 91, in edit_message
    updated_message = self.messagesRepository.update(message, **data)
                      ^^^^^^^^^^^^^^^^^^^^^^^^^^^^^^^^^^^^^^^^^^^^^^^
TypeError: Repository.update() got an unexpected keyword argument 'edited'
[35;1mHTTP PUT /api/classes/class/8ca5ca65-bd20-454c-b583-ad2bbd94ef27/message/197fb606-fb6c-476f-bc99-0575eabd15c3/ 500 [0.05, 127.0.0.1:58172][0m
Internal Server Error: /api/classes/class/8ca5ca65-bd20-454c-b583-ad2bbd94ef27/message/197fb606-fb6c-476f-bc99-0575eabd15c3/
Traceback (most recent call last):
  File "/Users/macuser/Desktop/django/online_class/venv/lib/python3.11/site-packages/asgiref/sync.py", line 534, in thread_handler
    raise exc_info[1]
  File "/Users/macuser/Desktop/django/online_class/venv/lib/python3.11/site-packages/django/core/handlers/exception.py", line 42, in inner
    response = await get_response(request)
               ^^^^^^^^^^^^^^^^^^^^^^^^^^^
  File "/Users/macuser/Desktop/django/online_class/venv/lib/python3.11/site-packages/asgiref/sync.py", line 534, in thread_handler
    raise exc_info[1]
  File "/Users/macuser/Desktop/django/online_class/venv/lib/python3.11/site-packages/django/core/handlers/base.py", line 253, in _get_response_async
    response = await wrapped_callback(
               ^^^^^^^^^^^^^^^^^^^^^^^
  File "/Users/macuser/Desktop/django/online_class/venv/lib/python3.11/site-packages/asgiref/sync.py", line 479, in __call__
    ret: _R = await loop.run_in_executor(
              ^^^^^^^^^^^^^^^^^^^^^^^^^^^
  File "/usr/local/Cellar/python@3.11/3.11.6_1/Frameworks/Python.framework/Versions/3.11/lib/python3.11/concurrent/futures/thread.py", line 58, in run
    result = self.fn(*self.args, **self.kwargs)
             ^^^^^^^^^^^^^^^^^^^^^^^^^^^^^^^^^^
  File "/Users/macuser/Desktop/django/online_class/venv/lib/python3.11/site-packages/asgiref/sync.py", line 538, in thread_handler
    return func(*args, **kwargs)
           ^^^^^^^^^^^^^^^^^^^^^
  File "/Users/macuser/Desktop/django/online_class/venv/lib/python3.11/site-packages/django/views/decorators/csrf.py", line 65, in _view_wrapper
    return view_func(request, *args, **kwargs)
           ^^^^^^^^^^^^^^^^^^^^^^^^^^^^^^^^^^^
  File "/Users/macuser/Desktop/django/online_class/venv/lib/python3.11/site-packages/django/views/generic/base.py", line 104, in view
    return self.dispatch(request, *args, **kwargs)
           ^^^^^^^^^^^^^^^^^^^^^^^^^^^^^^^^^^^^^^^
  File "/Users/macuser/Desktop/django/online_class/venv/lib/python3.11/site-packages/rest_framework/views.py", line 509, in dispatch
    response = self.handle_exception(exc)
               ^^^^^^^^^^^^^^^^^^^^^^^^^^
  File "/Users/macuser/Desktop/django/online_class/venv/lib/python3.11/site-packages/rest_framework/views.py", line 469, in handle_exception
    self.raise_uncaught_exception(exc)
  File "/Users/macuser/Desktop/django/online_class/venv/lib/python3.11/site-packages/rest_framework/views.py", line 480, in raise_uncaught_exception
    raise exc
  File "/Users/macuser/Desktop/django/online_class/venv/lib/python3.11/site-packages/rest_framework/views.py", line 506, in dispatch
    response = handler(request, *args, **kwargs)
               ^^^^^^^^^^^^^^^^^^^^^^^^^^^^^^^^^
  File "/Users/macuser/Desktop/django/online_class/project/classes/views.py", line 96, in put
    updated_message = service.edit_message(message, data)
                      ^^^^^^^^^^^^^^^^^^^^^^^^^^^^^^^^^^^
  File "/Users/macuser/Desktop/django/online_class/project/classes/services/class_service.py", line 91, in edit_message
    updated_message = self.messagesRepository.update(message, **data)
                      ^^^^^^^^^^^^^^^^^^^^^^^^^^^^^^^^^^^^^^^^^^^^^^^
TypeError: Repository.update() got an unexpected keyword argument 'edited'
[35;1mHTTP PUT /api/classes/class/8ca5ca65-bd20-454c-b583-ad2bbd94ef27/message/197fb606-fb6c-476f-bc99-0575eabd15c3/ 500 [0.05, 127.0.0.1:58172][0m
Internal Server Error: /api/classes/class/8ca5ca65-bd20-454c-b583-ad2bbd94ef27/message/197fb606-fb6c-476f-bc99-0575eabd15c3/
Traceback (most recent call last):
  File "/Users/macuser/Desktop/django/online_class/venv/lib/python3.11/site-packages/asgiref/sync.py", line 534, in thread_handler
    raise exc_info[1]
  File "/Users/macuser/Desktop/django/online_class/venv/lib/python3.11/site-packages/django/core/handlers/exception.py", line 42, in inner
    response = await get_response(request)
               ^^^^^^^^^^^^^^^^^^^^^^^^^^^
  File "/Users/macuser/Desktop/django/online_class/venv/lib/python3.11/site-packages/asgiref/sync.py", line 534, in thread_handler
    raise exc_info[1]
  File "/Users/macuser/Desktop/django/online_class/venv/lib/python3.11/site-packages/django/core/handlers/base.py", line 253, in _get_response_async
    response = await wrapped_callback(
               ^^^^^^^^^^^^^^^^^^^^^^^
  File "/Users/macuser/Desktop/django/online_class/venv/lib/python3.11/site-packages/asgiref/sync.py", line 479, in __call__
    ret: _R = await loop.run_in_executor(
              ^^^^^^^^^^^^^^^^^^^^^^^^^^^
  File "/usr/local/Cellar/python@3.11/3.11.6_1/Frameworks/Python.framework/Versions/3.11/lib/python3.11/concurrent/futures/thread.py", line 58, in run
    result = self.fn(*self.args, **self.kwargs)
             ^^^^^^^^^^^^^^^^^^^^^^^^^^^^^^^^^^
  File "/Users/macuser/Desktop/django/online_class/venv/lib/python3.11/site-packages/asgiref/sync.py", line 538, in thread_handler
    return func(*args, **kwargs)
           ^^^^^^^^^^^^^^^^^^^^^
  File "/Users/macuser/Desktop/django/online_class/venv/lib/python3.11/site-packages/django/views/decorators/csrf.py", line 65, in _view_wrapper
    return view_func(request, *args, **kwargs)
           ^^^^^^^^^^^^^^^^^^^^^^^^^^^^^^^^^^^
  File "/Users/macuser/Desktop/django/online_class/venv/lib/python3.11/site-packages/django/views/generic/base.py", line 104, in view
    return self.dispatch(request, *args, **kwargs)
           ^^^^^^^^^^^^^^^^^^^^^^^^^^^^^^^^^^^^^^^
  File "/Users/macuser/Desktop/django/online_class/venv/lib/python3.11/site-packages/rest_framework/views.py", line 509, in dispatch
    response = self.handle_exception(exc)
               ^^^^^^^^^^^^^^^^^^^^^^^^^^
  File "/Users/macuser/Desktop/django/online_class/venv/lib/python3.11/site-packages/rest_framework/views.py", line 469, in handle_exception
    self.raise_uncaught_exception(exc)
  File "/Users/macuser/Desktop/django/online_class/venv/lib/python3.11/site-packages/rest_framework/views.py", line 480, in raise_uncaught_exception
    raise exc
  File "/Users/macuser/Desktop/django/online_class/venv/lib/python3.11/site-packages/rest_framework/views.py", line 506, in dispatch
    response = handler(request, *args, **kwargs)
               ^^^^^^^^^^^^^^^^^^^^^^^^^^^^^^^^^
  File "/Users/macuser/Desktop/django/online_class/project/classes/views.py", line 96, in put
    updated_message = service.edit_message(message, data)
                      ^^^^^^^^^^^^^^^^^^^^^^^^^^^^^^^^^^^
  File "/Users/macuser/Desktop/django/online_class/project/classes/services/class_service.py", line 91, in edit_message
    updated_message = self.messagesRepository.update(message, **data)
                      ^^^^^^^^^^^^^^^^^^^^^^^^^^^^^^^^^^^^^^^^^^^^^^^
TypeError: Repository.update() got an unexpected keyword argument 'edited'
[35;1mHTTP PUT /api/classes/class/8ca5ca65-bd20-454c-b583-ad2bbd94ef27/message/197fb606-fb6c-476f-bc99-0575eabd15c3/ 500 [0.05, 127.0.0.1:58172][0m
Internal Server Error: /api/classes/class/8ca5ca65-bd20-454c-b583-ad2bbd94ef27/message/197fb606-fb6c-476f-bc99-0575eabd15c3/
Traceback (most recent call last):
  File "/Users/macuser/Desktop/django/online_class/venv/lib/python3.11/site-packages/asgiref/sync.py", line 534, in thread_handler
    raise exc_info[1]
  File "/Users/macuser/Desktop/django/online_class/venv/lib/python3.11/site-packages/django/core/handlers/exception.py", line 42, in inner
    response = await get_response(request)
               ^^^^^^^^^^^^^^^^^^^^^^^^^^^
  File "/Users/macuser/Desktop/django/online_class/venv/lib/python3.11/site-packages/asgiref/sync.py", line 534, in thread_handler
    raise exc_info[1]
  File "/Users/macuser/Desktop/django/online_class/venv/lib/python3.11/site-packages/django/core/handlers/base.py", line 253, in _get_response_async
    response = await wrapped_callback(
               ^^^^^^^^^^^^^^^^^^^^^^^
  File "/Users/macuser/Desktop/django/online_class/venv/lib/python3.11/site-packages/asgiref/sync.py", line 479, in __call__
    ret: _R = await loop.run_in_executor(
              ^^^^^^^^^^^^^^^^^^^^^^^^^^^
  File "/usr/local/Cellar/python@3.11/3.11.6_1/Frameworks/Python.framework/Versions/3.11/lib/python3.11/concurrent/futures/thread.py", line 58, in run
    result = self.fn(*self.args, **self.kwargs)
             ^^^^^^^^^^^^^^^^^^^^^^^^^^^^^^^^^^
  File "/Users/macuser/Desktop/django/online_class/venv/lib/python3.11/site-packages/asgiref/sync.py", line 538, in thread_handler
    return func(*args, **kwargs)
           ^^^^^^^^^^^^^^^^^^^^^
  File "/Users/macuser/Desktop/django/online_class/venv/lib/python3.11/site-packages/django/views/decorators/csrf.py", line 65, in _view_wrapper
    return view_func(request, *args, **kwargs)
           ^^^^^^^^^^^^^^^^^^^^^^^^^^^^^^^^^^^
  File "/Users/macuser/Desktop/django/online_class/venv/lib/python3.11/site-packages/django/views/generic/base.py", line 104, in view
    return self.dispatch(request, *args, **kwargs)
           ^^^^^^^^^^^^^^^^^^^^^^^^^^^^^^^^^^^^^^^
  File "/Users/macuser/Desktop/django/online_class/venv/lib/python3.11/site-packages/rest_framework/views.py", line 509, in dispatch
    response = self.handle_exception(exc)
               ^^^^^^^^^^^^^^^^^^^^^^^^^^
  File "/Users/macuser/Desktop/django/online_class/venv/lib/python3.11/site-packages/rest_framework/views.py", line 469, in handle_exception
    self.raise_uncaught_exception(exc)
  File "/Users/macuser/Desktop/django/online_class/venv/lib/python3.11/site-packages/rest_framework/views.py", line 480, in raise_uncaught_exception
    raise exc
  File "/Users/macuser/Desktop/django/online_class/venv/lib/python3.11/site-packages/rest_framework/views.py", line 506, in dispatch
    response = handler(request, *args, **kwargs)
               ^^^^^^^^^^^^^^^^^^^^^^^^^^^^^^^^^
  File "/Users/macuser/Desktop/django/online_class/project/classes/views.py", line 96, in put
    updated_message = service.edit_message(message, data)
                      ^^^^^^^^^^^^^^^^^^^^^^^^^^^^^^^^^^^
  File "/Users/macuser/Desktop/django/online_class/project/classes/services/class_service.py", line 91, in edit_message
    updated_message = self.messagesRepository.update(message, **data)
                      ^^^^^^^^^^^^^^^^^^^^^^^^^^^^^^^^^^^^^^^^^^^^^^^
TypeError: Repository.update() missing 1 required positional argument: 'validated_data'
[35;1mHTTP PUT /api/classes/class/8ca5ca65-bd20-454c-b583-ad2bbd94ef27/message/197fb606-fb6c-476f-bc99-0575eabd15c3/ 500 [0.07, 127.0.0.1:58197][0m
Internal Server Error: /api/classes/class/8ca5ca65-bd20-454c-b583-ad2bbd94ef27/message/197fb606-fb6c-476f-bc99-0575eabd15c3/
Traceback (most recent call last):
  File "/Users/macuser/Desktop/django/online_class/venv/lib/python3.11/site-packages/asgiref/sync.py", line 534, in thread_handler
    raise exc_info[1]
  File "/Users/macuser/Desktop/django/online_class/venv/lib/python3.11/site-packages/django/core/handlers/exception.py", line 42, in inner
    response = await get_response(request)
               ^^^^^^^^^^^^^^^^^^^^^^^^^^^
  File "/Users/macuser/Desktop/django/online_class/venv/lib/python3.11/site-packages/asgiref/sync.py", line 534, in thread_handler
    raise exc_info[1]
  File "/Users/macuser/Desktop/django/online_class/venv/lib/python3.11/site-packages/django/core/handlers/base.py", line 253, in _get_response_async
    response = await wrapped_callback(
               ^^^^^^^^^^^^^^^^^^^^^^^
  File "/Users/macuser/Desktop/django/online_class/venv/lib/python3.11/site-packages/asgiref/sync.py", line 479, in __call__
    ret: _R = await loop.run_in_executor(
              ^^^^^^^^^^^^^^^^^^^^^^^^^^^
  File "/usr/local/Cellar/python@3.11/3.11.6_1/Frameworks/Python.framework/Versions/3.11/lib/python3.11/concurrent/futures/thread.py", line 58, in run
    result = self.fn(*self.args, **self.kwargs)
             ^^^^^^^^^^^^^^^^^^^^^^^^^^^^^^^^^^
  File "/Users/macuser/Desktop/django/online_class/venv/lib/python3.11/site-packages/asgiref/sync.py", line 538, in thread_handler
    return func(*args, **kwargs)
           ^^^^^^^^^^^^^^^^^^^^^
  File "/Users/macuser/Desktop/django/online_class/venv/lib/python3.11/site-packages/django/views/decorators/csrf.py", line 65, in _view_wrapper
    return view_func(request, *args, **kwargs)
           ^^^^^^^^^^^^^^^^^^^^^^^^^^^^^^^^^^^
  File "/Users/macuser/Desktop/django/online_class/venv/lib/python3.11/site-packages/django/views/generic/base.py", line 104, in view
    return self.dispatch(request, *args, **kwargs)
           ^^^^^^^^^^^^^^^^^^^^^^^^^^^^^^^^^^^^^^^
  File "/Users/macuser/Desktop/django/online_class/venv/lib/python3.11/site-packages/rest_framework/views.py", line 509, in dispatch
    response = self.handle_exception(exc)
               ^^^^^^^^^^^^^^^^^^^^^^^^^^
  File "/Users/macuser/Desktop/django/online_class/venv/lib/python3.11/site-packages/rest_framework/views.py", line 469, in handle_exception
    self.raise_uncaught_exception(exc)
  File "/Users/macuser/Desktop/django/online_class/venv/lib/python3.11/site-packages/rest_framework/views.py", line 480, in raise_uncaught_exception
    raise exc
  File "/Users/macuser/Desktop/django/online_class/venv/lib/python3.11/site-packages/rest_framework/views.py", line 506, in dispatch
    response = handler(request, *args, **kwargs)
               ^^^^^^^^^^^^^^^^^^^^^^^^^^^^^^^^^
  File "/Users/macuser/Desktop/django/online_class/project/classes/views.py", line 96, in put
    updated_message = service.edit_message(message, data)
                      ^^^^^^^^^^^^^^^^^^^^^^^^^^^^^^^^^^^
  File "/Users/macuser/Desktop/django/online_class/project/classes/services/class_service.py", line 91, in edit_message
    updated_message = self.messagesRepository.update(message, **data)
                      ^^^^^^^^^^^^^^^^^^^^^^^^^^^^^^^^^^^^^^^^^^^^^^^
TypeError: Repository.update() missing 1 required positional argument: 'validated_data'
[35;1mHTTP PUT /api/classes/class/8ca5ca65-bd20-454c-b583-ad2bbd94ef27/message/197fb606-fb6c-476f-bc99-0575eabd15c3/ 500 [0.05, 127.0.0.1:58197][0m
Internal Server Error: /api/classes/class/8ca5ca65-bd20-454c-b583-ad2bbd94ef27/message/197fb606-fb6c-476f-bc99-0575eabd15c3/
Traceback (most recent call last):
  File "/Users/macuser/Desktop/django/online_class/venv/lib/python3.11/site-packages/asgiref/sync.py", line 534, in thread_handler
    raise exc_info[1]
  File "/Users/macuser/Desktop/django/online_class/venv/lib/python3.11/site-packages/django/core/handlers/exception.py", line 42, in inner
    response = await get_response(request)
               ^^^^^^^^^^^^^^^^^^^^^^^^^^^
  File "/Users/macuser/Desktop/django/online_class/venv/lib/python3.11/site-packages/asgiref/sync.py", line 534, in thread_handler
    raise exc_info[1]
  File "/Users/macuser/Desktop/django/online_class/venv/lib/python3.11/site-packages/django/core/handlers/base.py", line 253, in _get_response_async
    response = await wrapped_callback(
               ^^^^^^^^^^^^^^^^^^^^^^^
  File "/Users/macuser/Desktop/django/online_class/venv/lib/python3.11/site-packages/asgiref/sync.py", line 479, in __call__
    ret: _R = await loop.run_in_executor(
              ^^^^^^^^^^^^^^^^^^^^^^^^^^^
  File "/usr/local/Cellar/python@3.11/3.11.6_1/Frameworks/Python.framework/Versions/3.11/lib/python3.11/concurrent/futures/thread.py", line 58, in run
    result = self.fn(*self.args, **self.kwargs)
             ^^^^^^^^^^^^^^^^^^^^^^^^^^^^^^^^^^
  File "/Users/macuser/Desktop/django/online_class/venv/lib/python3.11/site-packages/asgiref/sync.py", line 538, in thread_handler
    return func(*args, **kwargs)
           ^^^^^^^^^^^^^^^^^^^^^
  File "/Users/macuser/Desktop/django/online_class/venv/lib/python3.11/site-packages/django/views/decorators/csrf.py", line 65, in _view_wrapper
    return view_func(request, *args, **kwargs)
           ^^^^^^^^^^^^^^^^^^^^^^^^^^^^^^^^^^^
  File "/Users/macuser/Desktop/django/online_class/venv/lib/python3.11/site-packages/django/views/generic/base.py", line 104, in view
    return self.dispatch(request, *args, **kwargs)
           ^^^^^^^^^^^^^^^^^^^^^^^^^^^^^^^^^^^^^^^
  File "/Users/macuser/Desktop/django/online_class/venv/lib/python3.11/site-packages/rest_framework/views.py", line 509, in dispatch
    response = self.handle_exception(exc)
               ^^^^^^^^^^^^^^^^^^^^^^^^^^
  File "/Users/macuser/Desktop/django/online_class/venv/lib/python3.11/site-packages/rest_framework/views.py", line 469, in handle_exception
    self.raise_uncaught_exception(exc)
  File "/Users/macuser/Desktop/django/online_class/venv/lib/python3.11/site-packages/rest_framework/views.py", line 480, in raise_uncaught_exception
    raise exc
  File "/Users/macuser/Desktop/django/online_class/venv/lib/python3.11/site-packages/rest_framework/views.py", line 506, in dispatch
    response = handler(request, *args, **kwargs)
               ^^^^^^^^^^^^^^^^^^^^^^^^^^^^^^^^^
  File "/Users/macuser/Desktop/django/online_class/project/classes/views.py", line 96, in put
    updated_message = service.edit_message(message, data)
                      ^^^^^^^^^^^^^^^^^^^^^^^^^^^^^^^^^^^
  File "/Users/macuser/Desktop/django/online_class/project/classes/services/class_service.py", line 91, in edit_message
    updated_message = self.messagesRepository.update2(message, **data)
                      ^^^^^^^^^^^^^^^^^^^^^^^^^^^^^^^^^^^^^^^^^^^^^^^^
  File "/Users/macuser/Desktop/django/online_class/project/repositories/repository.py", line 34, in update2
    instance.save()
    ^^^^^^^^^^^^^
AttributeError: 'ReturnDict' object has no attribute 'save'
[35;1mHTTP PUT /api/classes/class/8ca5ca65-bd20-454c-b583-ad2bbd94ef27/message/197fb606-fb6c-476f-bc99-0575eabd15c3/ 500 [0.13, 127.0.0.1:58207][0m
Internal Server Error: /api/classes/class/8ca5ca65-bd20-454c-b583-ad2bbd94ef27/message/197fb606-fb6c-476f-bc99-0575eabd15c3/
Traceback (most recent call last):
  File "/Users/macuser/Desktop/django/online_class/venv/lib/python3.11/site-packages/asgiref/sync.py", line 534, in thread_handler
    raise exc_info[1]
  File "/Users/macuser/Desktop/django/online_class/venv/lib/python3.11/site-packages/django/core/handlers/exception.py", line 42, in inner
    response = await get_response(request)
               ^^^^^^^^^^^^^^^^^^^^^^^^^^^
  File "/Users/macuser/Desktop/django/online_class/venv/lib/python3.11/site-packages/asgiref/sync.py", line 534, in thread_handler
    raise exc_info[1]
  File "/Users/macuser/Desktop/django/online_class/venv/lib/python3.11/site-packages/django/core/handlers/base.py", line 253, in _get_response_async
    response = await wrapped_callback(
               ^^^^^^^^^^^^^^^^^^^^^^^
  File "/Users/macuser/Desktop/django/online_class/venv/lib/python3.11/site-packages/asgiref/sync.py", line 479, in __call__
    ret: _R = await loop.run_in_executor(
              ^^^^^^^^^^^^^^^^^^^^^^^^^^^
  File "/usr/local/Cellar/python@3.11/3.11.6_1/Frameworks/Python.framework/Versions/3.11/lib/python3.11/concurrent/futures/thread.py", line 58, in run
    result = self.fn(*self.args, **self.kwargs)
             ^^^^^^^^^^^^^^^^^^^^^^^^^^^^^^^^^^
  File "/Users/macuser/Desktop/django/online_class/venv/lib/python3.11/site-packages/asgiref/sync.py", line 538, in thread_handler
    return func(*args, **kwargs)
           ^^^^^^^^^^^^^^^^^^^^^
  File "/Users/macuser/Desktop/django/online_class/venv/lib/python3.11/site-packages/django/views/decorators/csrf.py", line 65, in _view_wrapper
    return view_func(request, *args, **kwargs)
           ^^^^^^^^^^^^^^^^^^^^^^^^^^^^^^^^^^^
  File "/Users/macuser/Desktop/django/online_class/venv/lib/python3.11/site-packages/django/views/generic/base.py", line 104, in view
    return self.dispatch(request, *args, **kwargs)
           ^^^^^^^^^^^^^^^^^^^^^^^^^^^^^^^^^^^^^^^
  File "/Users/macuser/Desktop/django/online_class/venv/lib/python3.11/site-packages/rest_framework/views.py", line 509, in dispatch
    response = self.handle_exception(exc)
               ^^^^^^^^^^^^^^^^^^^^^^^^^^
  File "/Users/macuser/Desktop/django/online_class/venv/lib/python3.11/site-packages/rest_framework/views.py", line 469, in handle_exception
    self.raise_uncaught_exception(exc)
  File "/Users/macuser/Desktop/django/online_class/venv/lib/python3.11/site-packages/rest_framework/views.py", line 480, in raise_uncaught_exception
    raise exc
  File "/Users/macuser/Desktop/django/online_class/venv/lib/python3.11/site-packages/rest_framework/views.py", line 506, in dispatch
    response = handler(request, *args, **kwargs)
               ^^^^^^^^^^^^^^^^^^^^^^^^^^^^^^^^^
  File "/Users/macuser/Desktop/django/online_class/project/classes/views.py", line 96, in put
    updated_message = service.edit_message(message, data)
                      ^^^^^^^^^^^^^^^^^^^^^^^^^^^^^^^^^^^
  File "/Users/macuser/Desktop/django/online_class/project/classes/services/class_service.py", line 91, in edit_message
    updated_message = self.messagesRepository.update3(message, **data)
                      ^^^^^^^^^^^^^^^^^^^^^^^^^^^^^^^^^^^^^^^^^^^^^^^^
  File "/Users/macuser/Desktop/django/online_class/project/repositories/repository.py", line 33, in update3
    instance.save()
    ^^^^^^^^^^^^^
AttributeError: 'ReturnDict' object has no attribute 'save'
[35;1mHTTP PUT /api/classes/class/8ca5ca65-bd20-454c-b583-ad2bbd94ef27/message/197fb606-fb6c-476f-bc99-0575eabd15c3/ 500 [0.09, 127.0.0.1:58223][0m
Internal Server Error: /api/classes/class/8ca5ca65-bd20-454c-b583-ad2bbd94ef27/message/197fb606-fb6c-476f-bc99-0575eabd15c3/
Traceback (most recent call last):
  File "/Users/macuser/Desktop/django/online_class/venv/lib/python3.11/site-packages/asgiref/sync.py", line 534, in thread_handler
    raise exc_info[1]
  File "/Users/macuser/Desktop/django/online_class/venv/lib/python3.11/site-packages/django/core/handlers/exception.py", line 42, in inner
    response = await get_response(request)
               ^^^^^^^^^^^^^^^^^^^^^^^^^^^
  File "/Users/macuser/Desktop/django/online_class/venv/lib/python3.11/site-packages/asgiref/sync.py", line 534, in thread_handler
    raise exc_info[1]
  File "/Users/macuser/Desktop/django/online_class/venv/lib/python3.11/site-packages/django/core/handlers/base.py", line 253, in _get_response_async
    response = await wrapped_callback(
               ^^^^^^^^^^^^^^^^^^^^^^^
  File "/Users/macuser/Desktop/django/online_class/venv/lib/python3.11/site-packages/asgiref/sync.py", line 479, in __call__
    ret: _R = await loop.run_in_executor(
              ^^^^^^^^^^^^^^^^^^^^^^^^^^^
  File "/usr/local/Cellar/python@3.11/3.11.6_1/Frameworks/Python.framework/Versions/3.11/lib/python3.11/concurrent/futures/thread.py", line 58, in run
    result = self.fn(*self.args, **self.kwargs)
             ^^^^^^^^^^^^^^^^^^^^^^^^^^^^^^^^^^
  File "/Users/macuser/Desktop/django/online_class/venv/lib/python3.11/site-packages/asgiref/sync.py", line 538, in thread_handler
    return func(*args, **kwargs)
           ^^^^^^^^^^^^^^^^^^^^^
  File "/Users/macuser/Desktop/django/online_class/venv/lib/python3.11/site-packages/django/views/decorators/csrf.py", line 65, in _view_wrapper
    return view_func(request, *args, **kwargs)
           ^^^^^^^^^^^^^^^^^^^^^^^^^^^^^^^^^^^
  File "/Users/macuser/Desktop/django/online_class/venv/lib/python3.11/site-packages/django/views/generic/base.py", line 104, in view
    return self.dispatch(request, *args, **kwargs)
           ^^^^^^^^^^^^^^^^^^^^^^^^^^^^^^^^^^^^^^^
  File "/Users/macuser/Desktop/django/online_class/venv/lib/python3.11/site-packages/rest_framework/views.py", line 509, in dispatch
    response = self.handle_exception(exc)
               ^^^^^^^^^^^^^^^^^^^^^^^^^^
  File "/Users/macuser/Desktop/django/online_class/venv/lib/python3.11/site-packages/rest_framework/views.py", line 469, in handle_exception
    self.raise_uncaught_exception(exc)
  File "/Users/macuser/Desktop/django/online_class/venv/lib/python3.11/site-packages/rest_framework/views.py", line 480, in raise_uncaught_exception
    raise exc
  File "/Users/macuser/Desktop/django/online_class/venv/lib/python3.11/site-packages/rest_framework/views.py", line 506, in dispatch
    response = handler(request, *args, **kwargs)
               ^^^^^^^^^^^^^^^^^^^^^^^^^^^^^^^^^
  File "/Users/macuser/Desktop/django/online_class/project/classes/views.py", line 96, in put
    updated_message = service.edit_message(message, data)
                      ^^^^^^^^^^^^^^^^^^^^^^^^^^^^^^^^^^^
  File "/Users/macuser/Desktop/django/online_class/project/classes/services/class_service.py", line 91, in edit_message
    updated_message = self.messagesRepository.update3(message, **data)
                      ^^^^^^^^^^^^^^^^^^^^^^^^^^^^^^^^^^^^^^^^^^^^^^^^
  File "/Users/macuser/Desktop/django/online_class/project/repositories/repository.py", line 33, in update3
    instance.save()
    ^^^^^^^^^^^^^
AttributeError: 'ReturnDict' object has no attribute 'save'
[35;1mHTTP PUT /api/classes/class/8ca5ca65-bd20-454c-b583-ad2bbd94ef27/message/197fb606-fb6c-476f-bc99-0575eabd15c3/ 500 [0.12, 127.0.0.1:58227][0m
Internal Server Error: /api/classes/class/8ca5ca65-bd20-454c-b583-ad2bbd94ef27/message/197fb606-fb6c-476f-bc99-0575eabd15c3/
Traceback (most recent call last):
  File "/Users/macuser/Desktop/django/online_class/venv/lib/python3.11/site-packages/asgiref/sync.py", line 534, in thread_handler
    raise exc_info[1]
  File "/Users/macuser/Desktop/django/online_class/venv/lib/python3.11/site-packages/django/core/handlers/exception.py", line 42, in inner
    response = await get_response(request)
               ^^^^^^^^^^^^^^^^^^^^^^^^^^^
  File "/Users/macuser/Desktop/django/online_class/venv/lib/python3.11/site-packages/asgiref/sync.py", line 534, in thread_handler
    raise exc_info[1]
  File "/Users/macuser/Desktop/django/online_class/venv/lib/python3.11/site-packages/django/core/handlers/base.py", line 253, in _get_response_async
    response = await wrapped_callback(
               ^^^^^^^^^^^^^^^^^^^^^^^
  File "/Users/macuser/Desktop/django/online_class/venv/lib/python3.11/site-packages/asgiref/sync.py", line 479, in __call__
    ret: _R = await loop.run_in_executor(
              ^^^^^^^^^^^^^^^^^^^^^^^^^^^
  File "/usr/local/Cellar/python@3.11/3.11.6_1/Frameworks/Python.framework/Versions/3.11/lib/python3.11/concurrent/futures/thread.py", line 58, in run
    result = self.fn(*self.args, **self.kwargs)
             ^^^^^^^^^^^^^^^^^^^^^^^^^^^^^^^^^^
  File "/Users/macuser/Desktop/django/online_class/venv/lib/python3.11/site-packages/asgiref/sync.py", line 538, in thread_handler
    return func(*args, **kwargs)
           ^^^^^^^^^^^^^^^^^^^^^
  File "/Users/macuser/Desktop/django/online_class/venv/lib/python3.11/site-packages/django/views/decorators/csrf.py", line 65, in _view_wrapper
    return view_func(request, *args, **kwargs)
           ^^^^^^^^^^^^^^^^^^^^^^^^^^^^^^^^^^^
  File "/Users/macuser/Desktop/django/online_class/venv/lib/python3.11/site-packages/django/views/generic/base.py", line 104, in view
    return self.dispatch(request, *args, **kwargs)
           ^^^^^^^^^^^^^^^^^^^^^^^^^^^^^^^^^^^^^^^
  File "/Users/macuser/Desktop/django/online_class/venv/lib/python3.11/site-packages/rest_framework/views.py", line 509, in dispatch
    response = self.handle_exception(exc)
               ^^^^^^^^^^^^^^^^^^^^^^^^^^
  File "/Users/macuser/Desktop/django/online_class/venv/lib/python3.11/site-packages/rest_framework/views.py", line 469, in handle_exception
    self.raise_uncaught_exception(exc)
  File "/Users/macuser/Desktop/django/online_class/venv/lib/python3.11/site-packages/rest_framework/views.py", line 480, in raise_uncaught_exception
    raise exc
  File "/Users/macuser/Desktop/django/online_class/venv/lib/python3.11/site-packages/rest_framework/views.py", line 506, in dispatch
    response = handler(request, *args, **kwargs)
               ^^^^^^^^^^^^^^^^^^^^^^^^^^^^^^^^^
  File "/Users/macuser/Desktop/django/online_class/project/classes/views.py", line 96, in put
    updated_message = service.edit_message(message, data)
                      ^^^^^^^^^^^^^^^^^^^^^^^^^^^^^^^^^^^
  File "/Users/macuser/Desktop/django/online_class/project/classes/services/class_service.py", line 91, in edit_message
    updated_message = self.messagesRepository.update3(message, **data)
                      ^^^^^^^^^^^^^^^^^^^^^^^^^^^^^^^^^^^^^^^^^^^^^^^^
  File "/Users/macuser/Desktop/django/online_class/project/repositories/repository.py", line 33, in update3
    instance.save()
    ^^^^^^^^^^^^^
AttributeError: 'ReturnDict' object has no attribute 'save'
[35;1mHTTP PUT /api/classes/class/8ca5ca65-bd20-454c-b583-ad2bbd94ef27/message/197fb606-fb6c-476f-bc99-0575eabd15c3/ 500 [0.04, 127.0.0.1:58227][0m
Internal Server Error: /api/classes/class/8ca5ca65-bd20-454c-b583-ad2bbd94ef27/message/197fb606-fb6c-476f-bc99-0575eabd15c3/
Traceback (most recent call last):
  File "/Users/macuser/Desktop/django/online_class/venv/lib/python3.11/site-packages/asgiref/sync.py", line 534, in thread_handler
    raise exc_info[1]
  File "/Users/macuser/Desktop/django/online_class/venv/lib/python3.11/site-packages/django/core/handlers/exception.py", line 42, in inner
    response = await get_response(request)
               ^^^^^^^^^^^^^^^^^^^^^^^^^^^
  File "/Users/macuser/Desktop/django/online_class/venv/lib/python3.11/site-packages/asgiref/sync.py", line 534, in thread_handler
    raise exc_info[1]
  File "/Users/macuser/Desktop/django/online_class/venv/lib/python3.11/site-packages/django/core/handlers/base.py", line 253, in _get_response_async
    response = await wrapped_callback(
               ^^^^^^^^^^^^^^^^^^^^^^^
  File "/Users/macuser/Desktop/django/online_class/venv/lib/python3.11/site-packages/asgiref/sync.py", line 479, in __call__
    ret: _R = await loop.run_in_executor(
              ^^^^^^^^^^^^^^^^^^^^^^^^^^^
  File "/usr/local/Cellar/python@3.11/3.11.6_1/Frameworks/Python.framework/Versions/3.11/lib/python3.11/concurrent/futures/thread.py", line 58, in run
    result = self.fn(*self.args, **self.kwargs)
             ^^^^^^^^^^^^^^^^^^^^^^^^^^^^^^^^^^
  File "/Users/macuser/Desktop/django/online_class/venv/lib/python3.11/site-packages/asgiref/sync.py", line 538, in thread_handler
    return func(*args, **kwargs)
           ^^^^^^^^^^^^^^^^^^^^^
  File "/Users/macuser/Desktop/django/online_class/venv/lib/python3.11/site-packages/django/views/decorators/csrf.py", line 65, in _view_wrapper
    return view_func(request, *args, **kwargs)
           ^^^^^^^^^^^^^^^^^^^^^^^^^^^^^^^^^^^
  File "/Users/macuser/Desktop/django/online_class/venv/lib/python3.11/site-packages/django/views/generic/base.py", line 104, in view
    return self.dispatch(request, *args, **kwargs)
           ^^^^^^^^^^^^^^^^^^^^^^^^^^^^^^^^^^^^^^^
  File "/Users/macuser/Desktop/django/online_class/venv/lib/python3.11/site-packages/rest_framework/views.py", line 509, in dispatch
    response = self.handle_exception(exc)
               ^^^^^^^^^^^^^^^^^^^^^^^^^^
  File "/Users/macuser/Desktop/django/online_class/venv/lib/python3.11/site-packages/rest_framework/views.py", line 469, in handle_exception
    self.raise_uncaught_exception(exc)
  File "/Users/macuser/Desktop/django/online_class/venv/lib/python3.11/site-packages/rest_framework/views.py", line 480, in raise_uncaught_exception
    raise exc
  File "/Users/macuser/Desktop/django/online_class/venv/lib/python3.11/site-packages/rest_framework/views.py", line 506, in dispatch
    response = handler(request, *args, **kwargs)
               ^^^^^^^^^^^^^^^^^^^^^^^^^^^^^^^^^
  File "/Users/macuser/Desktop/django/online_class/project/classes/views.py", line 96, in put
    updated_message = service.edit_message(message, data)
                      ^^^^^^^^^^^^^^^^^^^^^^^^^^^^^^^^^^^
  File "/Users/macuser/Desktop/django/online_class/project/classes/services/class_service.py", line 91, in edit_message
    updated_message = self.messagesRepository.update3(message, **data)
                      ^^^^^^^^^^^^^^^^^^^^^^^^^^^^^^^^^^^^^^^^^^^^^^^^
  File "/Users/macuser/Desktop/django/online_class/project/repositories/repository.py", line 33, in update3
    instance.save()
    ^^^^^^^^^^^^^
AttributeError: 'ReturnDict' object has no attribute 'save'
[35;1mHTTP PUT /api/classes/class/8ca5ca65-bd20-454c-b583-ad2bbd94ef27/message/197fb606-fb6c-476f-bc99-0575eabd15c3/ 500 [0.08, 127.0.0.1:58262][0m
Internal Server Error: /api/classes/class/8ca5ca65-bd20-454c-b583-ad2bbd94ef27/message/197fb606-fb6c-476f-bc99-0575eabd15c3/
Traceback (most recent call last):
  File "/Users/macuser/Desktop/django/online_class/venv/lib/python3.11/site-packages/asgiref/sync.py", line 534, in thread_handler
    raise exc_info[1]
  File "/Users/macuser/Desktop/django/online_class/venv/lib/python3.11/site-packages/django/core/handlers/exception.py", line 42, in inner
    response = await get_response(request)
               ^^^^^^^^^^^^^^^^^^^^^^^^^^^
  File "/Users/macuser/Desktop/django/online_class/venv/lib/python3.11/site-packages/asgiref/sync.py", line 534, in thread_handler
    raise exc_info[1]
  File "/Users/macuser/Desktop/django/online_class/venv/lib/python3.11/site-packages/django/core/handlers/base.py", line 253, in _get_response_async
    response = await wrapped_callback(
               ^^^^^^^^^^^^^^^^^^^^^^^
  File "/Users/macuser/Desktop/django/online_class/venv/lib/python3.11/site-packages/asgiref/sync.py", line 479, in __call__
    ret: _R = await loop.run_in_executor(
              ^^^^^^^^^^^^^^^^^^^^^^^^^^^
  File "/usr/local/Cellar/python@3.11/3.11.6_1/Frameworks/Python.framework/Versions/3.11/lib/python3.11/concurrent/futures/thread.py", line 58, in run
    result = self.fn(*self.args, **self.kwargs)
             ^^^^^^^^^^^^^^^^^^^^^^^^^^^^^^^^^^
  File "/Users/macuser/Desktop/django/online_class/venv/lib/python3.11/site-packages/asgiref/sync.py", line 538, in thread_handler
    return func(*args, **kwargs)
           ^^^^^^^^^^^^^^^^^^^^^
  File "/Users/macuser/Desktop/django/online_class/venv/lib/python3.11/site-packages/django/views/decorators/csrf.py", line 65, in _view_wrapper
    return view_func(request, *args, **kwargs)
           ^^^^^^^^^^^^^^^^^^^^^^^^^^^^^^^^^^^
  File "/Users/macuser/Desktop/django/online_class/venv/lib/python3.11/site-packages/django/views/generic/base.py", line 104, in view
    return self.dispatch(request, *args, **kwargs)
           ^^^^^^^^^^^^^^^^^^^^^^^^^^^^^^^^^^^^^^^
  File "/Users/macuser/Desktop/django/online_class/venv/lib/python3.11/site-packages/rest_framework/views.py", line 509, in dispatch
    response = self.handle_exception(exc)
               ^^^^^^^^^^^^^^^^^^^^^^^^^^
  File "/Users/macuser/Desktop/django/online_class/venv/lib/python3.11/site-packages/rest_framework/views.py", line 469, in handle_exception
    self.raise_uncaught_exception(exc)
  File "/Users/macuser/Desktop/django/online_class/venv/lib/python3.11/site-packages/rest_framework/views.py", line 480, in raise_uncaught_exception
    raise exc
  File "/Users/macuser/Desktop/django/online_class/venv/lib/python3.11/site-packages/rest_framework/views.py", line 506, in dispatch
    response = handler(request, *args, **kwargs)
               ^^^^^^^^^^^^^^^^^^^^^^^^^^^^^^^^^
  File "/Users/macuser/Desktop/django/online_class/project/classes/views.py", line 96, in put
    updated_message = service.edit_message(message, data)
                      ^^^^^^^^^^^^^^^^^^^^^^^^^^^^^^^^^^^
  File "/Users/macuser/Desktop/django/online_class/project/classes/services/class_service.py", line 91, in edit_message
    updated_message = self.messagesRepository.update3(message, **data)
                      ^^^^^^^^^^^^^^^^^^^^^^^^^^^^^^^^^^^^^^^^^^^^^^^^
  File "/Users/macuser/Desktop/django/online_class/project/repositories/repository.py", line 33, in update3
    instance.save()
    ^^^^^^^^^^^^^
AttributeError: 'ReturnDict' object has no attribute 'save'
[35;1mHTTP PUT /api/classes/class/8ca5ca65-bd20-454c-b583-ad2bbd94ef27/message/197fb606-fb6c-476f-bc99-0575eabd15c3/ 500 [0.04, 127.0.0.1:58262][0m
Internal Server Error: /api/classes/class/8ca5ca65-bd20-454c-b583-ad2bbd94ef27/message/197fb606-fb6c-476f-bc99-0575eabd15c3/
Traceback (most recent call last):
  File "/Users/macuser/Desktop/django/online_class/venv/lib/python3.11/site-packages/asgiref/sync.py", line 534, in thread_handler
    raise exc_info[1]
  File "/Users/macuser/Desktop/django/online_class/venv/lib/python3.11/site-packages/django/core/handlers/exception.py", line 42, in inner
    response = await get_response(request)
               ^^^^^^^^^^^^^^^^^^^^^^^^^^^
  File "/Users/macuser/Desktop/django/online_class/venv/lib/python3.11/site-packages/asgiref/sync.py", line 534, in thread_handler
    raise exc_info[1]
  File "/Users/macuser/Desktop/django/online_class/venv/lib/python3.11/site-packages/django/core/handlers/base.py", line 253, in _get_response_async
    response = await wrapped_callback(
               ^^^^^^^^^^^^^^^^^^^^^^^
  File "/Users/macuser/Desktop/django/online_class/venv/lib/python3.11/site-packages/asgiref/sync.py", line 479, in __call__
    ret: _R = await loop.run_in_executor(
              ^^^^^^^^^^^^^^^^^^^^^^^^^^^
  File "/usr/local/Cellar/python@3.11/3.11.6_1/Frameworks/Python.framework/Versions/3.11/lib/python3.11/concurrent/futures/thread.py", line 58, in run
    result = self.fn(*self.args, **self.kwargs)
             ^^^^^^^^^^^^^^^^^^^^^^^^^^^^^^^^^^
  File "/Users/macuser/Desktop/django/online_class/venv/lib/python3.11/site-packages/asgiref/sync.py", line 538, in thread_handler
    return func(*args, **kwargs)
           ^^^^^^^^^^^^^^^^^^^^^
  File "/Users/macuser/Desktop/django/online_class/venv/lib/python3.11/site-packages/django/views/decorators/csrf.py", line 65, in _view_wrapper
    return view_func(request, *args, **kwargs)
           ^^^^^^^^^^^^^^^^^^^^^^^^^^^^^^^^^^^
  File "/Users/macuser/Desktop/django/online_class/venv/lib/python3.11/site-packages/django/views/generic/base.py", line 104, in view
    return self.dispatch(request, *args, **kwargs)
           ^^^^^^^^^^^^^^^^^^^^^^^^^^^^^^^^^^^^^^^
  File "/Users/macuser/Desktop/django/online_class/venv/lib/python3.11/site-packages/rest_framework/views.py", line 509, in dispatch
    response = self.handle_exception(exc)
               ^^^^^^^^^^^^^^^^^^^^^^^^^^
  File "/Users/macuser/Desktop/django/online_class/venv/lib/python3.11/site-packages/rest_framework/views.py", line 469, in handle_exception
    self.raise_uncaught_exception(exc)
  File "/Users/macuser/Desktop/django/online_class/venv/lib/python3.11/site-packages/rest_framework/views.py", line 480, in raise_uncaught_exception
    raise exc
  File "/Users/macuser/Desktop/django/online_class/venv/lib/python3.11/site-packages/rest_framework/views.py", line 506, in dispatch
    response = handler(request, *args, **kwargs)
               ^^^^^^^^^^^^^^^^^^^^^^^^^^^^^^^^^
  File "/Users/macuser/Desktop/django/online_class/project/classes/views.py", line 96, in put
    updated_message = service.edit_message(message, data)
                      ^^^^^^^^^^^^^^^^^^^^^^^^^^^^^^^^^^^
  File "/Users/macuser/Desktop/django/online_class/project/classes/services/class_service.py", line 91, in edit_message
    updated_message = self.messagesRepository.update3(message, **data)
                      ^^^^^^^^^^^^^^^^^^^^^^^^^^^^^^^^^^^^^^^^^^^^^^^^
  File "/Users/macuser/Desktop/django/online_class/project/repositories/repository.py", line 33, in update3
    instance.save()
    ^^^^^^^^^^^^^
AttributeError: 'ReturnDict' object has no attribute 'save'
[35;1mHTTP PUT /api/classes/class/8ca5ca65-bd20-454c-b583-ad2bbd94ef27/message/197fb606-fb6c-476f-bc99-0575eabd15c3/ 500 [0.19, 127.0.0.1:58272][0m
Internal Server Error: /api/classes/class/8ca5ca65-bd20-454c-b583-ad2bbd94ef27/message/197fb606-fb6c-476f-bc99-0575eabd15c3/
Traceback (most recent call last):
  File "/Users/macuser/Desktop/django/online_class/venv/lib/python3.11/site-packages/asgiref/sync.py", line 534, in thread_handler
    raise exc_info[1]
  File "/Users/macuser/Desktop/django/online_class/venv/lib/python3.11/site-packages/django/core/handlers/exception.py", line 42, in inner
    response = await get_response(request)
               ^^^^^^^^^^^^^^^^^^^^^^^^^^^
  File "/Users/macuser/Desktop/django/online_class/venv/lib/python3.11/site-packages/asgiref/sync.py", line 534, in thread_handler
    raise exc_info[1]
  File "/Users/macuser/Desktop/django/online_class/venv/lib/python3.11/site-packages/django/core/handlers/base.py", line 253, in _get_response_async
    response = await wrapped_callback(
               ^^^^^^^^^^^^^^^^^^^^^^^
  File "/Users/macuser/Desktop/django/online_class/venv/lib/python3.11/site-packages/asgiref/sync.py", line 479, in __call__
    ret: _R = await loop.run_in_executor(
              ^^^^^^^^^^^^^^^^^^^^^^^^^^^
  File "/usr/local/Cellar/python@3.11/3.11.6_1/Frameworks/Python.framework/Versions/3.11/lib/python3.11/concurrent/futures/thread.py", line 58, in run
    result = self.fn(*self.args, **self.kwargs)
             ^^^^^^^^^^^^^^^^^^^^^^^^^^^^^^^^^^
  File "/Users/macuser/Desktop/django/online_class/venv/lib/python3.11/site-packages/asgiref/sync.py", line 538, in thread_handler
    return func(*args, **kwargs)
           ^^^^^^^^^^^^^^^^^^^^^
  File "/Users/macuser/Desktop/django/online_class/venv/lib/python3.11/site-packages/django/views/decorators/csrf.py", line 65, in _view_wrapper
    return view_func(request, *args, **kwargs)
           ^^^^^^^^^^^^^^^^^^^^^^^^^^^^^^^^^^^
  File "/Users/macuser/Desktop/django/online_class/venv/lib/python3.11/site-packages/django/views/generic/base.py", line 104, in view
    return self.dispatch(request, *args, **kwargs)
           ^^^^^^^^^^^^^^^^^^^^^^^^^^^^^^^^^^^^^^^
  File "/Users/macuser/Desktop/django/online_class/venv/lib/python3.11/site-packages/rest_framework/views.py", line 509, in dispatch
    response = self.handle_exception(exc)
               ^^^^^^^^^^^^^^^^^^^^^^^^^^
  File "/Users/macuser/Desktop/django/online_class/venv/lib/python3.11/site-packages/rest_framework/views.py", line 469, in handle_exception
    self.raise_uncaught_exception(exc)
  File "/Users/macuser/Desktop/django/online_class/venv/lib/python3.11/site-packages/rest_framework/views.py", line 480, in raise_uncaught_exception
    raise exc
  File "/Users/macuser/Desktop/django/online_class/venv/lib/python3.11/site-packages/rest_framework/views.py", line 506, in dispatch
    response = handler(request, *args, **kwargs)
               ^^^^^^^^^^^^^^^^^^^^^^^^^^^^^^^^^
  File "/Users/macuser/Desktop/django/online_class/project/classes/views.py", line 96, in put
    updated_message = service.edit_message(message, data)
                      ^^^^^^^^^^^^^^^^^^^^^^^^^^^^^^^^^^^
  File "/Users/macuser/Desktop/django/online_class/project/classes/services/class_service.py", line 91, in edit_message
    updated_message = self.messagesRepository.update3(message, **data)
                      ^^^^^^^^^^^^^^^^^^^^^^^^^^^^^^^^^^^^^^^^^^^^^^^^
  File "/Users/macuser/Desktop/django/online_class/project/repositories/repository.py", line 31, in update3
    instance.save()
    ^^^^^^^^^^^^^
AttributeError: 'ReturnDict' object has no attribute 'save'
[35;1mHTTP PUT /api/classes/class/8ca5ca65-bd20-454c-b583-ad2bbd94ef27/message/197fb606-fb6c-476f-bc99-0575eabd15c3/ 500 [0.12, 127.0.0.1:58279][0m
Internal Server Error: /api/classes/class/8ca5ca65-bd20-454c-b583-ad2bbd94ef27/message/197fb606-fb6c-476f-bc99-0575eabd15c3/
Traceback (most recent call last):
  File "/Users/macuser/Desktop/django/online_class/venv/lib/python3.11/site-packages/asgiref/sync.py", line 534, in thread_handler
    raise exc_info[1]
  File "/Users/macuser/Desktop/django/online_class/venv/lib/python3.11/site-packages/django/core/handlers/exception.py", line 42, in inner
    response = await get_response(request)
               ^^^^^^^^^^^^^^^^^^^^^^^^^^^
  File "/Users/macuser/Desktop/django/online_class/venv/lib/python3.11/site-packages/asgiref/sync.py", line 534, in thread_handler
    raise exc_info[1]
  File "/Users/macuser/Desktop/django/online_class/venv/lib/python3.11/site-packages/django/core/handlers/base.py", line 253, in _get_response_async
    response = await wrapped_callback(
               ^^^^^^^^^^^^^^^^^^^^^^^
  File "/Users/macuser/Desktop/django/online_class/venv/lib/python3.11/site-packages/asgiref/sync.py", line 479, in __call__
    ret: _R = await loop.run_in_executor(
              ^^^^^^^^^^^^^^^^^^^^^^^^^^^
  File "/usr/local/Cellar/python@3.11/3.11.6_1/Frameworks/Python.framework/Versions/3.11/lib/python3.11/concurrent/futures/thread.py", line 58, in run
    result = self.fn(*self.args, **self.kwargs)
             ^^^^^^^^^^^^^^^^^^^^^^^^^^^^^^^^^^
  File "/Users/macuser/Desktop/django/online_class/venv/lib/python3.11/site-packages/asgiref/sync.py", line 538, in thread_handler
    return func(*args, **kwargs)
           ^^^^^^^^^^^^^^^^^^^^^
  File "/Users/macuser/Desktop/django/online_class/venv/lib/python3.11/site-packages/django/views/decorators/csrf.py", line 65, in _view_wrapper
    return view_func(request, *args, **kwargs)
           ^^^^^^^^^^^^^^^^^^^^^^^^^^^^^^^^^^^
  File "/Users/macuser/Desktop/django/online_class/venv/lib/python3.11/site-packages/django/views/generic/base.py", line 104, in view
    return self.dispatch(request, *args, **kwargs)
           ^^^^^^^^^^^^^^^^^^^^^^^^^^^^^^^^^^^^^^^
  File "/Users/macuser/Desktop/django/online_class/venv/lib/python3.11/site-packages/rest_framework/views.py", line 509, in dispatch
    response = self.handle_exception(exc)
               ^^^^^^^^^^^^^^^^^^^^^^^^^^
  File "/Users/macuser/Desktop/django/online_class/venv/lib/python3.11/site-packages/rest_framework/views.py", line 469, in handle_exception
    self.raise_uncaught_exception(exc)
  File "/Users/macuser/Desktop/django/online_class/venv/lib/python3.11/site-packages/rest_framework/views.py", line 480, in raise_uncaught_exception
    raise exc
  File "/Users/macuser/Desktop/django/online_class/venv/lib/python3.11/site-packages/rest_framework/views.py", line 506, in dispatch
    response = handler(request, *args, **kwargs)
               ^^^^^^^^^^^^^^^^^^^^^^^^^^^^^^^^^
  File "/Users/macuser/Desktop/django/online_class/project/classes/views.py", line 96, in put
    updated_message = service.edit_message(request.user, class_id, message_id, data)
                      ^^^^^^^^^^^^^^^^^^^^^^^^^^^^^^^^^^^^^^^^^^^^^^^^^^^^^^^^^^^^^^
TypeError: ClassService.edit_message() takes 4 positional arguments but 5 were given
[35;1mHTTP PUT /api/classes/class/8ca5ca65-bd20-454c-b583-ad2bbd94ef27/message/197fb606-fb6c-476f-bc99-0575eabd15c3/ 500 [0.14, 127.0.0.1:58323][0m
Internal Server Error: /api/classes/class/8ca5ca65-bd20-454c-b583-ad2bbd94ef27/message/197fb606-fb6c-476f-bc99-0575eabd15c3/
Traceback (most recent call last):
  File "/Users/macuser/Desktop/django/online_class/venv/lib/python3.11/site-packages/asgiref/sync.py", line 534, in thread_handler
    raise exc_info[1]
  File "/Users/macuser/Desktop/django/online_class/venv/lib/python3.11/site-packages/django/core/handlers/exception.py", line 42, in inner
    response = await get_response(request)
               ^^^^^^^^^^^^^^^^^^^^^^^^^^^
  File "/Users/macuser/Desktop/django/online_class/venv/lib/python3.11/site-packages/asgiref/sync.py", line 534, in thread_handler
    raise exc_info[1]
  File "/Users/macuser/Desktop/django/online_class/venv/lib/python3.11/site-packages/django/core/handlers/base.py", line 253, in _get_response_async
    response = await wrapped_callback(
               ^^^^^^^^^^^^^^^^^^^^^^^
  File "/Users/macuser/Desktop/django/online_class/venv/lib/python3.11/site-packages/asgiref/sync.py", line 479, in __call__
    ret: _R = await loop.run_in_executor(
              ^^^^^^^^^^^^^^^^^^^^^^^^^^^
  File "/usr/local/Cellar/python@3.11/3.11.6_1/Frameworks/Python.framework/Versions/3.11/lib/python3.11/concurrent/futures/thread.py", line 58, in run
    result = self.fn(*self.args, **self.kwargs)
             ^^^^^^^^^^^^^^^^^^^^^^^^^^^^^^^^^^
  File "/Users/macuser/Desktop/django/online_class/venv/lib/python3.11/site-packages/asgiref/sync.py", line 538, in thread_handler
    return func(*args, **kwargs)
           ^^^^^^^^^^^^^^^^^^^^^
  File "/Users/macuser/Desktop/django/online_class/venv/lib/python3.11/site-packages/django/views/decorators/csrf.py", line 65, in _view_wrapper
    return view_func(request, *args, **kwargs)
           ^^^^^^^^^^^^^^^^^^^^^^^^^^^^^^^^^^^
  File "/Users/macuser/Desktop/django/online_class/venv/lib/python3.11/site-packages/django/views/generic/base.py", line 104, in view
    return self.dispatch(request, *args, **kwargs)
           ^^^^^^^^^^^^^^^^^^^^^^^^^^^^^^^^^^^^^^^
  File "/Users/macuser/Desktop/django/online_class/venv/lib/python3.11/site-packages/rest_framework/views.py", line 509, in dispatch
    response = self.handle_exception(exc)
               ^^^^^^^^^^^^^^^^^^^^^^^^^^
  File "/Users/macuser/Desktop/django/online_class/venv/lib/python3.11/site-packages/rest_framework/views.py", line 469, in handle_exception
    self.raise_uncaught_exception(exc)
  File "/Users/macuser/Desktop/django/online_class/venv/lib/python3.11/site-packages/rest_framework/views.py", line 480, in raise_uncaught_exception
    raise exc
  File "/Users/macuser/Desktop/django/online_class/venv/lib/python3.11/site-packages/rest_framework/views.py", line 506, in dispatch
    response = handler(request, *args, **kwargs)
               ^^^^^^^^^^^^^^^^^^^^^^^^^^^^^^^^^
  File "/Users/macuser/Desktop/django/online_class/project/classes/views.py", line 96, in put
    updated_message = service.edit_message(request.user, class_id, message_id, data)
                      ^^^^^^^^^^^^^^^^^^^^^^^^^^^^^^^^^^^^^^^^^^^^^^^^^^^^^^^^^^^^^^
TypeError: ClassService.edit_message() takes 4 positional arguments but 5 were given
[35;1mHTTP PUT /api/classes/class/8ca5ca65-bd20-454c-b583-ad2bbd94ef27/message/197fb606-fb6c-476f-bc99-0575eabd15c3/ 500 [0.04, 127.0.0.1:58323][0m
Internal Server Error: /api/classes/class/8ca5ca65-bd20-454c-b583-ad2bbd94ef27/message/197fb606-fb6c-476f-bc99-0575eabd15c3/
Traceback (most recent call last):
  File "/Users/macuser/Desktop/django/online_class/venv/lib/python3.11/site-packages/asgiref/sync.py", line 534, in thread_handler
    raise exc_info[1]
  File "/Users/macuser/Desktop/django/online_class/venv/lib/python3.11/site-packages/django/core/handlers/exception.py", line 42, in inner
    response = await get_response(request)
               ^^^^^^^^^^^^^^^^^^^^^^^^^^^
  File "/Users/macuser/Desktop/django/online_class/venv/lib/python3.11/site-packages/asgiref/sync.py", line 534, in thread_handler
    raise exc_info[1]
  File "/Users/macuser/Desktop/django/online_class/venv/lib/python3.11/site-packages/django/core/handlers/base.py", line 253, in _get_response_async
    response = await wrapped_callback(
               ^^^^^^^^^^^^^^^^^^^^^^^
  File "/Users/macuser/Desktop/django/online_class/venv/lib/python3.11/site-packages/asgiref/sync.py", line 479, in __call__
    ret: _R = await loop.run_in_executor(
              ^^^^^^^^^^^^^^^^^^^^^^^^^^^
  File "/usr/local/Cellar/python@3.11/3.11.6_1/Frameworks/Python.framework/Versions/3.11/lib/python3.11/concurrent/futures/thread.py", line 58, in run
    result = self.fn(*self.args, **self.kwargs)
             ^^^^^^^^^^^^^^^^^^^^^^^^^^^^^^^^^^
  File "/Users/macuser/Desktop/django/online_class/venv/lib/python3.11/site-packages/asgiref/sync.py", line 538, in thread_handler
    return func(*args, **kwargs)
           ^^^^^^^^^^^^^^^^^^^^^
  File "/Users/macuser/Desktop/django/online_class/venv/lib/python3.11/site-packages/django/views/decorators/csrf.py", line 65, in _view_wrapper
    return view_func(request, *args, **kwargs)
           ^^^^^^^^^^^^^^^^^^^^^^^^^^^^^^^^^^^
  File "/Users/macuser/Desktop/django/online_class/venv/lib/python3.11/site-packages/django/views/generic/base.py", line 104, in view
    return self.dispatch(request, *args, **kwargs)
           ^^^^^^^^^^^^^^^^^^^^^^^^^^^^^^^^^^^^^^^
  File "/Users/macuser/Desktop/django/online_class/venv/lib/python3.11/site-packages/rest_framework/views.py", line 509, in dispatch
    response = self.handle_exception(exc)
               ^^^^^^^^^^^^^^^^^^^^^^^^^^
  File "/Users/macuser/Desktop/django/online_class/venv/lib/python3.11/site-packages/rest_framework/views.py", line 469, in handle_exception
    self.raise_uncaught_exception(exc)
  File "/Users/macuser/Desktop/django/online_class/venv/lib/python3.11/site-packages/rest_framework/views.py", line 480, in raise_uncaught_exception
    raise exc
  File "/Users/macuser/Desktop/django/online_class/venv/lib/python3.11/site-packages/rest_framework/views.py", line 506, in dispatch
    response = handler(request, *args, **kwargs)
               ^^^^^^^^^^^^^^^^^^^^^^^^^^^^^^^^^
  File "/Users/macuser/Desktop/django/online_class/project/classes/views.py", line 96, in put
    updated_message = service.edit_message(request.user, class_id, message_id, data)
                      ^^^^^^^^^^^^^^^^^^^^^^^^^^^^^^^^^^^^^^^^^^^^^^^^^^^^^^^^^^^^^^
TypeError: ClassService.edit_message() takes 4 positional arguments but 5 were given
[35;1mHTTP PUT /api/classes/class/8ca5ca65-bd20-454c-b583-ad2bbd94ef27/message/197fb606-fb6c-476f-bc99-0575eabd15c3/ 500 [0.05, 127.0.0.1:58323][0m
Internal Server Error: /api/classes/class/8ca5ca65-bd20-454c-b583-ad2bbd94ef27/message/197fb606-fb6c-476f-bc99-0575eabd15c3/
Traceback (most recent call last):
  File "/Users/macuser/Desktop/django/online_class/venv/lib/python3.11/site-packages/asgiref/sync.py", line 534, in thread_handler
    raise exc_info[1]
  File "/Users/macuser/Desktop/django/online_class/venv/lib/python3.11/site-packages/django/core/handlers/exception.py", line 42, in inner
    response = await get_response(request)
               ^^^^^^^^^^^^^^^^^^^^^^^^^^^
  File "/Users/macuser/Desktop/django/online_class/venv/lib/python3.11/site-packages/asgiref/sync.py", line 534, in thread_handler
    raise exc_info[1]
  File "/Users/macuser/Desktop/django/online_class/venv/lib/python3.11/site-packages/django/core/handlers/base.py", line 253, in _get_response_async
    response = await wrapped_callback(
               ^^^^^^^^^^^^^^^^^^^^^^^
  File "/Users/macuser/Desktop/django/online_class/venv/lib/python3.11/site-packages/asgiref/sync.py", line 479, in __call__
    ret: _R = await loop.run_in_executor(
              ^^^^^^^^^^^^^^^^^^^^^^^^^^^
  File "/usr/local/Cellar/python@3.11/3.11.6_1/Frameworks/Python.framework/Versions/3.11/lib/python3.11/concurrent/futures/thread.py", line 58, in run
    result = self.fn(*self.args, **self.kwargs)
             ^^^^^^^^^^^^^^^^^^^^^^^^^^^^^^^^^^
  File "/Users/macuser/Desktop/django/online_class/venv/lib/python3.11/site-packages/asgiref/sync.py", line 538, in thread_handler
    return func(*args, **kwargs)
           ^^^^^^^^^^^^^^^^^^^^^
  File "/Users/macuser/Desktop/django/online_class/venv/lib/python3.11/site-packages/django/views/decorators/csrf.py", line 65, in _view_wrapper
    return view_func(request, *args, **kwargs)
           ^^^^^^^^^^^^^^^^^^^^^^^^^^^^^^^^^^^
  File "/Users/macuser/Desktop/django/online_class/venv/lib/python3.11/site-packages/django/views/generic/base.py", line 104, in view
    return self.dispatch(request, *args, **kwargs)
           ^^^^^^^^^^^^^^^^^^^^^^^^^^^^^^^^^^^^^^^
  File "/Users/macuser/Desktop/django/online_class/venv/lib/python3.11/site-packages/rest_framework/views.py", line 509, in dispatch
    response = self.handle_exception(exc)
               ^^^^^^^^^^^^^^^^^^^^^^^^^^
  File "/Users/macuser/Desktop/django/online_class/venv/lib/python3.11/site-packages/rest_framework/views.py", line 469, in handle_exception
    self.raise_uncaught_exception(exc)
  File "/Users/macuser/Desktop/django/online_class/venv/lib/python3.11/site-packages/rest_framework/views.py", line 480, in raise_uncaught_exception
    raise exc
  File "/Users/macuser/Desktop/django/online_class/venv/lib/python3.11/site-packages/rest_framework/views.py", line 506, in dispatch
    response = handler(request, *args, **kwargs)
               ^^^^^^^^^^^^^^^^^^^^^^^^^^^^^^^^^
  File "/Users/macuser/Desktop/django/online_class/project/classes/views.py", line 91, in put
    updated_message = service.edit_message(class_id, message_id, data)
                      ^^^^^^^^^^^^^^^^^^^^^^^^^^^^^^^^^^^^^^^^^^^^^^^^
  File "/Users/macuser/Desktop/django/online_class/project/classes/services/class_service.py", line 90, in edit_message
    updated_message = self.messagesRepository.update(message, **data)
                      ^^^^^^^^^^^^^^^^^^^^^^^^^^^^^^^^^^^^^^^^^^^^^^^
TypeError: Repository.update() got an unexpected keyword argument 'text'
[35;1mHTTP PUT /api/classes/class/8ca5ca65-bd20-454c-b583-ad2bbd94ef27/message/197fb606-fb6c-476f-bc99-0575eabd15c3/ 500 [0.20, 127.0.0.1:58429][0m
Internal Server Error: /api/classes/class/8ca5ca65-bd20-454c-b583-ad2bbd94ef27/message/197fb606-fb6c-476f-bc99-0575eabd15c3/
Traceback (most recent call last):
  File "/Users/macuser/Desktop/django/online_class/venv/lib/python3.11/site-packages/asgiref/sync.py", line 534, in thread_handler
    raise exc_info[1]
  File "/Users/macuser/Desktop/django/online_class/venv/lib/python3.11/site-packages/django/core/handlers/exception.py", line 42, in inner
    response = await get_response(request)
               ^^^^^^^^^^^^^^^^^^^^^^^^^^^
  File "/Users/macuser/Desktop/django/online_class/venv/lib/python3.11/site-packages/asgiref/sync.py", line 534, in thread_handler
    raise exc_info[1]
  File "/Users/macuser/Desktop/django/online_class/venv/lib/python3.11/site-packages/django/core/handlers/base.py", line 253, in _get_response_async
    response = await wrapped_callback(
               ^^^^^^^^^^^^^^^^^^^^^^^
  File "/Users/macuser/Desktop/django/online_class/venv/lib/python3.11/site-packages/asgiref/sync.py", line 479, in __call__
    ret: _R = await loop.run_in_executor(
              ^^^^^^^^^^^^^^^^^^^^^^^^^^^
  File "/usr/local/Cellar/python@3.11/3.11.6_1/Frameworks/Python.framework/Versions/3.11/lib/python3.11/concurrent/futures/thread.py", line 58, in run
    result = self.fn(*self.args, **self.kwargs)
             ^^^^^^^^^^^^^^^^^^^^^^^^^^^^^^^^^^
  File "/Users/macuser/Desktop/django/online_class/venv/lib/python3.11/site-packages/asgiref/sync.py", line 538, in thread_handler
    return func(*args, **kwargs)
           ^^^^^^^^^^^^^^^^^^^^^
  File "/Users/macuser/Desktop/django/online_class/venv/lib/python3.11/site-packages/django/views/decorators/csrf.py", line 65, in _view_wrapper
    return view_func(request, *args, **kwargs)
           ^^^^^^^^^^^^^^^^^^^^^^^^^^^^^^^^^^^
  File "/Users/macuser/Desktop/django/online_class/venv/lib/python3.11/site-packages/django/views/generic/base.py", line 104, in view
    return self.dispatch(request, *args, **kwargs)
           ^^^^^^^^^^^^^^^^^^^^^^^^^^^^^^^^^^^^^^^
  File "/Users/macuser/Desktop/django/online_class/venv/lib/python3.11/site-packages/rest_framework/views.py", line 509, in dispatch
    response = self.handle_exception(exc)
               ^^^^^^^^^^^^^^^^^^^^^^^^^^
  File "/Users/macuser/Desktop/django/online_class/venv/lib/python3.11/site-packages/rest_framework/views.py", line 469, in handle_exception
    self.raise_uncaught_exception(exc)
  File "/Users/macuser/Desktop/django/online_class/venv/lib/python3.11/site-packages/rest_framework/views.py", line 480, in raise_uncaught_exception
    raise exc
  File "/Users/macuser/Desktop/django/online_class/venv/lib/python3.11/site-packages/rest_framework/views.py", line 506, in dispatch
    response = handler(request, *args, **kwargs)
               ^^^^^^^^^^^^^^^^^^^^^^^^^^^^^^^^^
  File "/Users/macuser/Desktop/django/online_class/project/classes/views.py", line 104, in delete
    service.delete_message(class_id, message_id)
TypeError: ClassService.delete_message() missing 1 required positional argument: 'data'
[35;1mHTTP DELETE /api/classes/class/8ca5ca65-bd20-454c-b583-ad2bbd94ef27/message/197fb606-fb6c-476f-bc99-0575eabd15c3/ 500 [0.08, 127.0.0.1:58498][0m
Internal Server Error: /api/user/user-profile/
Traceback (most recent call last):
  File "/Users/macuser/Desktop/django/online_class/venv/lib/python3.11/site-packages/asgiref/sync.py", line 534, in thread_handler
    raise exc_info[1]
  File "/Users/macuser/Desktop/django/online_class/venv/lib/python3.11/site-packages/django/core/handlers/exception.py", line 42, in inner
    response = await get_response(request)
               ^^^^^^^^^^^^^^^^^^^^^^^^^^^
  File "/Users/macuser/Desktop/django/online_class/venv/lib/python3.11/site-packages/asgiref/sync.py", line 534, in thread_handler
    raise exc_info[1]
  File "/Users/macuser/Desktop/django/online_class/venv/lib/python3.11/site-packages/django/core/handlers/base.py", line 253, in _get_response_async
    response = await wrapped_callback(
               ^^^^^^^^^^^^^^^^^^^^^^^
  File "/Users/macuser/Desktop/django/online_class/venv/lib/python3.11/site-packages/asgiref/sync.py", line 479, in __call__
    ret: _R = await loop.run_in_executor(
              ^^^^^^^^^^^^^^^^^^^^^^^^^^^
  File "/usr/local/Cellar/python@3.11/3.11.6_1/Frameworks/Python.framework/Versions/3.11/lib/python3.11/concurrent/futures/thread.py", line 58, in run
    result = self.fn(*self.args, **self.kwargs)
             ^^^^^^^^^^^^^^^^^^^^^^^^^^^^^^^^^^
  File "/Users/macuser/Desktop/django/online_class/venv/lib/python3.11/site-packages/asgiref/sync.py", line 538, in thread_handler
    return func(*args, **kwargs)
           ^^^^^^^^^^^^^^^^^^^^^
  File "/Users/macuser/Desktop/django/online_class/venv/lib/python3.11/site-packages/django/views/decorators/csrf.py", line 65, in _view_wrapper
    return view_func(request, *args, **kwargs)
           ^^^^^^^^^^^^^^^^^^^^^^^^^^^^^^^^^^^
  File "/Users/macuser/Desktop/django/online_class/venv/lib/python3.11/site-packages/django/views/generic/base.py", line 104, in view
    return self.dispatch(request, *args, **kwargs)
           ^^^^^^^^^^^^^^^^^^^^^^^^^^^^^^^^^^^^^^^
  File "/Users/macuser/Desktop/django/online_class/venv/lib/python3.11/site-packages/rest_framework/views.py", line 509, in dispatch
    response = self.handle_exception(exc)
               ^^^^^^^^^^^^^^^^^^^^^^^^^^
  File "/Users/macuser/Desktop/django/online_class/venv/lib/python3.11/site-packages/rest_framework/views.py", line 469, in handle_exception
    self.raise_uncaught_exception(exc)
  File "/Users/macuser/Desktop/django/online_class/venv/lib/python3.11/site-packages/rest_framework/views.py", line 480, in raise_uncaught_exception
    raise exc
  File "/Users/macuser/Desktop/django/online_class/venv/lib/python3.11/site-packages/rest_framework/views.py", line 506, in dispatch
    response = handler(request, *args, **kwargs)
               ^^^^^^^^^^^^^^^^^^^^^^^^^^^^^^^^^
  File "/Users/macuser/Desktop/django/online_class/project/user/views.py", line 28, in get
    return Response(serializer.data)
                    ^^^^^^^^^^^^^^^
  File "/Users/macuser/Desktop/django/online_class/venv/lib/python3.11/site-packages/rest_framework/serializers.py", line 555, in data
    ret = super().data
          ^^^^^^^^^^^^
  File "/Users/macuser/Desktop/django/online_class/venv/lib/python3.11/site-packages/rest_framework/serializers.py", line 253, in data
    self._data = self.to_representation(self.instance)
                 ^^^^^^^^^^^^^^^^^^^^^^^^^^^^^^^^^^^^^
  File "/Users/macuser/Desktop/django/online_class/venv/lib/python3.11/site-packages/rest_framework/serializers.py", line 522, in to_representation
    ret[field.field_name] = field.to_representation(attribute)
                            ^^^^^^^^^^^^^^^^^^^^^^^^^^^^^^^^^^
  File "/Users/macuser/Desktop/django/online_class/venv/lib/python3.11/site-packages/rest_framework/fields.py", line 1838, in to_representation
    return method(value)
           ^^^^^^^^^^^^^
  File "/Users/macuser/Desktop/django/online_class/project/user/serializers.py", line 19, in get_profile_status
    return obj.user.username
    ^^^^^^^^
AttributeError: 'User' object has no attribute 'user'
[35;1mHTTP GET /api/user/user-profile/ 500 [0.09, 127.0.0.1:60586][0m
Internal Server Error: /api/user/user-profile/
Traceback (most recent call last):
  File "/Users/macuser/Desktop/django/online_class/venv/lib/python3.11/site-packages/asgiref/sync.py", line 534, in thread_handler
    raise exc_info[1]
  File "/Users/macuser/Desktop/django/online_class/venv/lib/python3.11/site-packages/django/core/handlers/exception.py", line 42, in inner
    response = await get_response(request)
               ^^^^^^^^^^^^^^^^^^^^^^^^^^^
  File "/Users/macuser/Desktop/django/online_class/venv/lib/python3.11/site-packages/asgiref/sync.py", line 534, in thread_handler
    raise exc_info[1]
  File "/Users/macuser/Desktop/django/online_class/venv/lib/python3.11/site-packages/django/core/handlers/base.py", line 253, in _get_response_async
    response = await wrapped_callback(
               ^^^^^^^^^^^^^^^^^^^^^^^
  File "/Users/macuser/Desktop/django/online_class/venv/lib/python3.11/site-packages/asgiref/sync.py", line 479, in __call__
    ret: _R = await loop.run_in_executor(
              ^^^^^^^^^^^^^^^^^^^^^^^^^^^
  File "/usr/local/Cellar/python@3.11/3.11.6_1/Frameworks/Python.framework/Versions/3.11/lib/python3.11/concurrent/futures/thread.py", line 58, in run
    result = self.fn(*self.args, **self.kwargs)
             ^^^^^^^^^^^^^^^^^^^^^^^^^^^^^^^^^^
  File "/Users/macuser/Desktop/django/online_class/venv/lib/python3.11/site-packages/asgiref/sync.py", line 538, in thread_handler
    return func(*args, **kwargs)
           ^^^^^^^^^^^^^^^^^^^^^
  File "/Users/macuser/Desktop/django/online_class/venv/lib/python3.11/site-packages/django/views/decorators/csrf.py", line 65, in _view_wrapper
    return view_func(request, *args, **kwargs)
           ^^^^^^^^^^^^^^^^^^^^^^^^^^^^^^^^^^^
  File "/Users/macuser/Desktop/django/online_class/venv/lib/python3.11/site-packages/django/views/generic/base.py", line 104, in view
    return self.dispatch(request, *args, **kwargs)
           ^^^^^^^^^^^^^^^^^^^^^^^^^^^^^^^^^^^^^^^
  File "/Users/macuser/Desktop/django/online_class/venv/lib/python3.11/site-packages/rest_framework/views.py", line 509, in dispatch
    response = self.handle_exception(exc)
               ^^^^^^^^^^^^^^^^^^^^^^^^^^
  File "/Users/macuser/Desktop/django/online_class/venv/lib/python3.11/site-packages/rest_framework/views.py", line 469, in handle_exception
    self.raise_uncaught_exception(exc)
  File "/Users/macuser/Desktop/django/online_class/venv/lib/python3.11/site-packages/rest_framework/views.py", line 480, in raise_uncaught_exception
    raise exc
  File "/Users/macuser/Desktop/django/online_class/venv/lib/python3.11/site-packages/rest_framework/views.py", line 506, in dispatch
    response = handler(request, *args, **kwargs)
               ^^^^^^^^^^^^^^^^^^^^^^^^^^^^^^^^^
  File "/Users/macuser/Desktop/django/online_class/project/user/views.py", line 28, in get
    return Response(serializer.data)
                    ^^^^^^^^^^^^^^^
  File "/Users/macuser/Desktop/django/online_class/venv/lib/python3.11/site-packages/rest_framework/serializers.py", line 555, in data
    ret = super().data
          ^^^^^^^^^^^^
  File "/Users/macuser/Desktop/django/online_class/venv/lib/python3.11/site-packages/rest_framework/serializers.py", line 253, in data
    self._data = self.to_representation(self.instance)
                 ^^^^^^^^^^^^^^^^^^^^^^^^^^^^^^^^^^^^^
  File "/Users/macuser/Desktop/django/online_class/venv/lib/python3.11/site-packages/rest_framework/serializers.py", line 522, in to_representation
    ret[field.field_name] = field.to_representation(attribute)
                            ^^^^^^^^^^^^^^^^^^^^^^^^^^^^^^^^^^
  File "/Users/macuser/Desktop/django/online_class/venv/lib/python3.11/site-packages/rest_framework/fields.py", line 1838, in to_representation
    return method(value)
           ^^^^^^^^^^^^^
  File "/Users/macuser/Desktop/django/online_class/project/user/serializers.py", line 19, in get_profile_status
    if obj.request.delete == True:
       ^^^^^^^^^^^
AttributeError: 'User' object has no attribute 'request'
[35;1mHTTP GET /api/user/user-profile/ 500 [0.09, 127.0.0.1:60979][0m
Internal Server Error: /api/user/user-profile/
Traceback (most recent call last):
  File "/Users/macuser/Desktop/django/online_class/venv/lib/python3.11/site-packages/asgiref/sync.py", line 534, in thread_handler
    raise exc_info[1]
  File "/Users/macuser/Desktop/django/online_class/venv/lib/python3.11/site-packages/django/core/handlers/exception.py", line 42, in inner
    response = await get_response(request)
               ^^^^^^^^^^^^^^^^^^^^^^^^^^^
  File "/Users/macuser/Desktop/django/online_class/venv/lib/python3.11/site-packages/asgiref/sync.py", line 534, in thread_handler
    raise exc_info[1]
  File "/Users/macuser/Desktop/django/online_class/venv/lib/python3.11/site-packages/django/core/handlers/base.py", line 253, in _get_response_async
    response = await wrapped_callback(
               ^^^^^^^^^^^^^^^^^^^^^^^
  File "/Users/macuser/Desktop/django/online_class/venv/lib/python3.11/site-packages/asgiref/sync.py", line 479, in __call__
    ret: _R = await loop.run_in_executor(
              ^^^^^^^^^^^^^^^^^^^^^^^^^^^
  File "/usr/local/Cellar/python@3.11/3.11.6_1/Frameworks/Python.framework/Versions/3.11/lib/python3.11/concurrent/futures/thread.py", line 58, in run
    result = self.fn(*self.args, **self.kwargs)
             ^^^^^^^^^^^^^^^^^^^^^^^^^^^^^^^^^^
  File "/Users/macuser/Desktop/django/online_class/venv/lib/python3.11/site-packages/asgiref/sync.py", line 538, in thread_handler
    return func(*args, **kwargs)
           ^^^^^^^^^^^^^^^^^^^^^
  File "/Users/macuser/Desktop/django/online_class/venv/lib/python3.11/site-packages/django/views/decorators/csrf.py", line 65, in _view_wrapper
    return view_func(request, *args, **kwargs)
           ^^^^^^^^^^^^^^^^^^^^^^^^^^^^^^^^^^^
  File "/Users/macuser/Desktop/django/online_class/venv/lib/python3.11/site-packages/django/views/generic/base.py", line 104, in view
    return self.dispatch(request, *args, **kwargs)
           ^^^^^^^^^^^^^^^^^^^^^^^^^^^^^^^^^^^^^^^
  File "/Users/macuser/Desktop/django/online_class/venv/lib/python3.11/site-packages/rest_framework/views.py", line 509, in dispatch
    response = self.handle_exception(exc)
               ^^^^^^^^^^^^^^^^^^^^^^^^^^
  File "/Users/macuser/Desktop/django/online_class/venv/lib/python3.11/site-packages/rest_framework/views.py", line 469, in handle_exception
    self.raise_uncaught_exception(exc)
  File "/Users/macuser/Desktop/django/online_class/venv/lib/python3.11/site-packages/rest_framework/views.py", line 480, in raise_uncaught_exception
    raise exc
  File "/Users/macuser/Desktop/django/online_class/venv/lib/python3.11/site-packages/rest_framework/views.py", line 506, in dispatch
    response = handler(request, *args, **kwargs)
               ^^^^^^^^^^^^^^^^^^^^^^^^^^^^^^^^^
  File "/Users/macuser/Desktop/django/online_class/project/user/views.py", line 28, in get
    return Response(serializer.data)
                    ^^^^^^^^^^^^^^^
  File "/Users/macuser/Desktop/django/online_class/venv/lib/python3.11/site-packages/rest_framework/serializers.py", line 555, in data
    ret = super().data
          ^^^^^^^^^^^^
  File "/Users/macuser/Desktop/django/online_class/venv/lib/python3.11/site-packages/rest_framework/serializers.py", line 253, in data
    self._data = self.to_representation(self.instance)
                 ^^^^^^^^^^^^^^^^^^^^^^^^^^^^^^^^^^^^^
  File "/Users/macuser/Desktop/django/online_class/venv/lib/python3.11/site-packages/rest_framework/serializers.py", line 522, in to_representation
    ret[field.field_name] = field.to_representation(attribute)
                            ^^^^^^^^^^^^^^^^^^^^^^^^^^^^^^^^^^
  File "/Users/macuser/Desktop/django/online_class/venv/lib/python3.11/site-packages/rest_framework/fields.py", line 1838, in to_representation
    return method(value)
           ^^^^^^^^^^^^^
  File "/Users/macuser/Desktop/django/online_class/project/user/serializers.py", line 21, in get_profile_status
    elapsed = timezone.now() - obj.deleted_date
              ~~~~~~~~~~~~~~~^~~~~~~~~~~~~~~~~~
TypeError: unsupported operand type(s) for -: 'datetime.datetime' and 'NoneType'
[35;1mHTTP GET /api/user/user-profile/ 500 [0.17, 127.0.0.1:62251][0m
Internal Server Error: /api/admin-user/users/
Traceback (most recent call last):
  File "/Users/macuser/Desktop/django/online_class/venv/lib/python3.11/site-packages/asgiref/sync.py", line 534, in thread_handler
    raise exc_info[1]
  File "/Users/macuser/Desktop/django/online_class/venv/lib/python3.11/site-packages/django/core/handlers/exception.py", line 42, in inner
    response = await get_response(request)
               ^^^^^^^^^^^^^^^^^^^^^^^^^^^
  File "/Users/macuser/Desktop/django/online_class/venv/lib/python3.11/site-packages/asgiref/sync.py", line 534, in thread_handler
    raise exc_info[1]
  File "/Users/macuser/Desktop/django/online_class/venv/lib/python3.11/site-packages/django/core/handlers/base.py", line 253, in _get_response_async
    response = await wrapped_callback(
               ^^^^^^^^^^^^^^^^^^^^^^^
  File "/Users/macuser/Desktop/django/online_class/venv/lib/python3.11/site-packages/asgiref/sync.py", line 479, in __call__
    ret: _R = await loop.run_in_executor(
              ^^^^^^^^^^^^^^^^^^^^^^^^^^^
  File "/usr/local/Cellar/python@3.11/3.11.6_1/Frameworks/Python.framework/Versions/3.11/lib/python3.11/concurrent/futures/thread.py", line 58, in run
    result = self.fn(*self.args, **self.kwargs)
             ^^^^^^^^^^^^^^^^^^^^^^^^^^^^^^^^^^
  File "/Users/macuser/Desktop/django/online_class/venv/lib/python3.11/site-packages/asgiref/sync.py", line 538, in thread_handler
    return func(*args, **kwargs)
           ^^^^^^^^^^^^^^^^^^^^^
  File "/Users/macuser/Desktop/django/online_class/venv/lib/python3.11/site-packages/django/views/decorators/csrf.py", line 65, in _view_wrapper
    return view_func(request, *args, **kwargs)
           ^^^^^^^^^^^^^^^^^^^^^^^^^^^^^^^^^^^
  File "/Users/macuser/Desktop/django/online_class/venv/lib/python3.11/site-packages/django/views/generic/base.py", line 104, in view
    return self.dispatch(request, *args, **kwargs)
           ^^^^^^^^^^^^^^^^^^^^^^^^^^^^^^^^^^^^^^^
  File "/Users/macuser/Desktop/django/online_class/venv/lib/python3.11/site-packages/rest_framework/views.py", line 509, in dispatch
    response = self.handle_exception(exc)
               ^^^^^^^^^^^^^^^^^^^^^^^^^^
  File "/Users/macuser/Desktop/django/online_class/venv/lib/python3.11/site-packages/rest_framework/views.py", line 469, in handle_exception
    self.raise_uncaught_exception(exc)
  File "/Users/macuser/Desktop/django/online_class/venv/lib/python3.11/site-packages/rest_framework/views.py", line 480, in raise_uncaught_exception
    raise exc
  File "/Users/macuser/Desktop/django/online_class/venv/lib/python3.11/site-packages/rest_framework/views.py", line 506, in dispatch
    response = handler(request, *args, **kwargs)
               ^^^^^^^^^^^^^^^^^^^^^^^^^^^^^^^^^
  File "/Users/macuser/Desktop/django/online_class/project/admin_user/views.py", line 225, in get
    users_data = admin_service.get_all_users(filters)
                 ^^^^^^^^^^^^^^^^^^^^^^^^^^^^^^^^^^^^
  File "/Users/macuser/Desktop/django/online_class/project/admin_user/services/admin_service.py", line 22, in get_all_users
    return serializer.data
          ^^^^^^^^^^^^^^^
  File "/Users/macuser/Desktop/django/online_class/venv/lib/python3.11/site-packages/rest_framework/serializers.py", line 768, in data
    ret = super().data
          ^^^^^^^^^^^^
  File "/Users/macuser/Desktop/django/online_class/venv/lib/python3.11/site-packages/rest_framework/serializers.py", line 253, in data
    self._data = self.to_representation(self.instance)
                 ^^^^^^^^^^^^^^^^^^^^^^^^^^^^^^^^^^^^^
  File "/Users/macuser/Desktop/django/online_class/venv/lib/python3.11/site-packages/rest_framework/serializers.py", line 686, in to_representation
    return [
           ^
  File "/Users/macuser/Desktop/django/online_class/venv/lib/python3.11/site-packages/rest_framework/serializers.py", line 687, in <listcomp>
    self.child.to_representation(item) for item in iterable
    ^^^^^^^^^^^^^^^^^^^^^^^^^^^^^^^^^^
  File "/Users/macuser/Desktop/django/online_class/venv/lib/python3.11/site-packages/rest_framework/serializers.py", line 522, in to_representation
    ret[field.field_name] = field.to_representation(attribute)
                            ^^^^^^^^^^^^^^^^^^^^^^^^^^^^^^^^^^
  File "/Users/macuser/Desktop/django/online_class/venv/lib/python3.11/site-packages/rest_framework/fields.py", line 1838, in to_representation
    return method(value)
           ^^^^^^^^^^^^^
  File "/Users/macuser/Desktop/django/online_class/project/admin_user/serializers.py", line 226, in get_profile_status
    elapsed = timezone.now() - obj.deleted_date
              ~~~~~~~~~~~~~~~^~~~~~~~~~~~~~~~~~
TypeError: unsupported operand type(s) for -: 'datetime.datetime' and 'NoneType'
[35;1mHTTP GET /api/admin-user/users/?deleted=yes 500 [0.19, 127.0.0.1:63243][0m
Internal Server Error: /api/admin-user/cancel-delete-profile-request/4
Traceback (most recent call last):
  File "/Users/macuser/Desktop/django/online_class/venv/lib/python3.11/site-packages/asgiref/sync.py", line 534, in thread_handler
    raise exc_info[1]
  File "/Users/macuser/Desktop/django/online_class/venv/lib/python3.11/site-packages/django/core/handlers/exception.py", line 42, in inner
    response = await get_response(request)
               ^^^^^^^^^^^^^^^^^^^^^^^^^^^
  File "/Users/macuser/Desktop/django/online_class/venv/lib/python3.11/site-packages/asgiref/sync.py", line 534, in thread_handler
    raise exc_info[1]
  File "/Users/macuser/Desktop/django/online_class/venv/lib/python3.11/site-packages/django/core/handlers/base.py", line 253, in _get_response_async
    response = await wrapped_callback(
               ^^^^^^^^^^^^^^^^^^^^^^^
  File "/Users/macuser/Desktop/django/online_class/venv/lib/python3.11/site-packages/asgiref/sync.py", line 479, in __call__
    ret: _R = await loop.run_in_executor(
              ^^^^^^^^^^^^^^^^^^^^^^^^^^^
  File "/usr/local/Cellar/python@3.11/3.11.6_1/Frameworks/Python.framework/Versions/3.11/lib/python3.11/concurrent/futures/thread.py", line 58, in run
    result = self.fn(*self.args, **self.kwargs)
             ^^^^^^^^^^^^^^^^^^^^^^^^^^^^^^^^^^
  File "/Users/macuser/Desktop/django/online_class/venv/lib/python3.11/site-packages/asgiref/sync.py", line 538, in thread_handler
    return func(*args, **kwargs)
           ^^^^^^^^^^^^^^^^^^^^^
  File "/Users/macuser/Desktop/django/online_class/venv/lib/python3.11/site-packages/django/views/decorators/csrf.py", line 65, in _view_wrapper
    return view_func(request, *args, **kwargs)
           ^^^^^^^^^^^^^^^^^^^^^^^^^^^^^^^^^^^
  File "/Users/macuser/Desktop/django/online_class/venv/lib/python3.11/site-packages/django/views/generic/base.py", line 104, in view
    return self.dispatch(request, *args, **kwargs)
           ^^^^^^^^^^^^^^^^^^^^^^^^^^^^^^^^^^^^^^^
  File "/Users/macuser/Desktop/django/online_class/venv/lib/python3.11/site-packages/rest_framework/views.py", line 509, in dispatch
    response = self.handle_exception(exc)
               ^^^^^^^^^^^^^^^^^^^^^^^^^^
  File "/Users/macuser/Desktop/django/online_class/venv/lib/python3.11/site-packages/rest_framework/views.py", line 469, in handle_exception
    self.raise_uncaught_exception(exc)
  File "/Users/macuser/Desktop/django/online_class/venv/lib/python3.11/site-packages/rest_framework/views.py", line 480, in raise_uncaught_exception
    raise exc
  File "/Users/macuser/Desktop/django/online_class/venv/lib/python3.11/site-packages/rest_framework/views.py", line 506, in dispatch
    response = handler(request, *args, **kwargs)
               ^^^^^^^^^^^^^^^^^^^^^^^^^^^^^^^^^
  File "/Users/macuser/Desktop/django/online_class/project/admin_user/views.py", line 252, in post
    serializer.save()
  File "/Users/macuser/Desktop/django/online_class/venv/lib/python3.11/site-packages/rest_framework/serializers.py", line 207, in save
    self.instance = self.update(self.instance, validated_data)
                    ^^^^^^^^^^^^^^^^^^^^^^^^^^^^^^^^^^^^^^^^^^
  File "/Users/macuser/Desktop/django/online_class/project/admin_user/serializers.py", line 277, in update
    instance.deleted_date = None
                            ^
NameError: name 'N' is not defined
[35;1mHTTP POST /api/admin-user/cancel-delete-profile-request/4 500 [0.09, 127.0.0.1:51858][0m
